Workbook

Sheet Matches
A1: MatchID | B1: Opponent | C1: Team Runs | D1: Team Wickets Lost | E1: Team Overs Played | F1: Opponent Runs | G1: Opponent Wickets Lost | H1: Opponent Overs Played | I1: Tournament | J1: Round | K1: MatchType | L1: Overs | M1: Date | N1: Time | O1: Venue | P1: Ball Material | Q1: Ball Color | R1: Toss | S1: Decision | T1: Innings Type | U1: Match Result
A2: 18418557 | B2: APJ Kalam Team | C2: 119 | D2: 10 | E2: 19.2 | F2: 268 | G2: 3 | H2: 23 | I2: Practice Match | J2: NA | K2: Limited Overs | L2: 23 | M2: 45864 | N2: 0.58333333 | O2: SGB ground | P2: Leather | Q2: Red | R2: Lost | S2: NA | T2: Chasing | U2: Lost
A3: 18642464 | B3: Katta 11s | C3: 225 | D3: 10 | E3: 29.2 | F3: 250 | G3: 6 | H3: 30 | I3: Practice Match | J3: NA | K3: Limited Overs | L3: 30 | M3: 45878 | N3: 0.31597222 | O3: Youth Ground Madhavaram | P3: Leather | Q3: Red | R3: Lost | S3: NA | T3: Chasing | U3: Lost
A4: 19019010 | B4: Rising Mavericks CC | C4: 141 | D4: 8 | E4: 25.5 | F4: 164 | G4: 10 | H4: 29.5 | I4: Practice Match | J4: NA | K4: Limited Overs | L4: 30 | M4: 45906 | N4: 0.54097222 | O4: Youth Ground Madhavaram | P4: Leather | Q4: Red | R4: Lost | S4: NA | T4: Chasing | U4: No Result
A5: 19112746 | B5: Dangerous Youth B | C5: 227 | D5: 10 | E5: 29.5 | F5: 227 | G5: 10 | H5: 29.4 | I5: Practice Match | J5: NA | K5: Limited Overs | L5: 30 | M5: 45913 | N5: 0.56458333 | O5: Youth Ground Madhavaram | P5: Leather | Q5: Red | R5: Won | S5: Batting First | T5: Batting First | U5: Tie
A6: 19859354 | B6: Team 404 | C6: 153 | D6: 8 | E6: 21 | F6: 210 | G6: 5 | H6: 21 | I6: Practice Match | J6: NA | K6: Limited Overs | L6: 21 | M6: 45959 | N6: 0.775 | O6: Agni College Ground | P6: Leather | Q6: White | R6: Lost | S6: NA | T6: Chasing | U6: Lost
A7: 19989363 | B7: Real Rulers | C7: 67 | D7: 10 | E7: 17.2 | F7: 83 | G7: 10 | H7: 15.4 | I7: Practice Match | J7: NA | K7: Limited Overs | L7: 25 | M7: 45969 | N7: 0.44444444 | O7: BELIEVERS EDEN GARDEN GROUND | P7: Leather | Q7: Red | R7: Lost | S7: NA | T7: Chasing | U7: Lost
A8: 20156519 | B8: Tea Kada Rajassss | C8: 126 | D8: 10 | E8: 18.3 | F8: 127 | G8: 5 | H8: 18.1 | I8: Practice Match | J8: NA | K8: Limited Overs | L8: 22 | M8: 45976 | N8: 0.44513889 | O8: BELIEVERS EDEN GARDEN GROUND | P8: Leather | Q8: Red | R8: Won | S8: Batting First | T8: Batting FIrst | U8: Lost
A9: 13848394 | B9: Deadly Elevens | C9: 110 | D9: 10 | E9: 20.3 | F9: 161 | G9: 8 | H9: 25 | I9: Practice Match | J9: NA | K9: Limited Overs | L9: 25 | M9: 45996 | N9: 0.97638889 | O9: Agni College Ground | P9: Leather | Q9: White | R9: Lost | S9: NA | T9: Chasing | U9: Lost
A10: 20648752 | B10: Shadowfax Hurricanes | C10: 144 | D10: 6 | E10: 23 | F10: 147 | G10: 3 | H10: 17.5 | I10: Practice Match | J10: NA | K10: Limited Overs | L10: 23 | M10: 46004 | N10: 0.4375 | O10: BELIEVERS EDEN GARDEN GROUND | P10: Leather | Q10: White | R10: Lost | S10: NA | T10: Batting FIrst | U10: Lost

Sheet Players
A1: PlayerID | B1: Player Name | C1: Role | D1: Bat Style | E1: Bowl Style
A2: P01 | B2: Sriram A | C2: All-rounder | D2: RHB | E2: RAM
A3: P02 | B3: Gautam Raj | C3: All-rounder | D3: RHB | E3: RAM
A4: P03 | B4: Jai | C4: All-rounder | D4: RHB | E4: RAM
A5: P04 | B5: Jeeva | C5: All-rounder | D5: RHB | E5: RAS
A6: P05 | B6: Naveen | C6: Bowler | D6: RHB | E6: RAS
A7: P06 | B7: Sanjay V | C7: All-rounder | D7: RHB | E7: RAM
A8: P07 | B8: Saravanan G | C8: Wicket-keeper | D8: RHB | E8: RAM
A9: P08 | B9: Senthil kumar | C9: Bowler | D9: RHB | E9: RAM
A10: P09 | B10: Shivaganesh | C10: All-rounder | D10: RHB | E10: RAM
A11: P10 | B11: Tharun M | C11: Wicket-keeper | D11: RHB | E11: NA
A12: P11 | B12: Vikram | C12: Bowler | D12: RHB | E12: RAM
... A26: P25 | B26: Vivek VNA | C26: Bowler | D26: RHB | E26: RAM

Sheet Batting
A1: MatchID | B1: PlayerID | C1: Runs | D1: Balls | E1: Fours | F1: Sixes | G1: Out | H1: Dismissal Type | I1: Strike Rate
A2: 18418557 | B2: P01 | C2: 53 | D2: 41 | E2: 9 | F2: 0 | G2: Yes | H2: Caught
A3: 18418557 | B3: P02 | C3: 3 | D3: 9 | E3: 0 | F3: 0 | G3: Yes | H3: Caught
A4: 18418557 | B4: P09 | C4: 5 | D4: 12 | E4: 1 | F4: 0 | G4: Yes | H4: Caught
A5: 18418557 | B5: P07 | C5: 4 | D5: 8 | E5: 1 | F5: 0 | G5: Yes | H5: Bowled
A6: 18418557 | B6: P06 | C6: 13 | D6: 13 | E6: 3 | F6: 0 | G6: Yes | H6: Caught
A7: 18418557 | B7: P04 | C7: 1 | D7: 6 | E7: 0 | F7: 0 | G7: Yes | H7: Caught
A8: 18418557 | B8: P03 | C8: 13 | D8: 16 | E8: 2 | F8: 0 | G8: No | H8: Not Out
A9: 18418557 | B9: P10 | C9: 0 | D9: 1 | E9: 0 | F9: 0 | G9: Yes | H9: Caught
A10: 18418557 | B10: P08 | C10: 1 | D10: 6 | E10: 0 | F10: 0 | G10: Yes | H10: Run Out
A11: 18418557 | B11: P11 | C11: 0 | D11: 1 | E11: 0 | F11: 0 | G11: Yes | H11: Run Out
A12: 18418557 | B12: P05 | C12: 4 | D12: 6 | E12: 1 | F12: 0 | G12: Yes | H12: Bowled
A13: 18642464 | B13: P09 | C13: 48 | D13: 38 | E13: 8 | F13: 1 | G13: Yes | H13: LBW
... A95: 20156519 | B95: P21 | C95: 0 | D95: 5 | E95: 0 | F95: 0 | G95: Yes | H95: Bowled

Sheet Bowling
A1: MatchID | B1: PlayerID | C1: Overs | D1: Maidens | E1: Runs | F1: Wickets | G1: Dots | H1: Fours | I1: Sixes | J1: Wides | K1: No-Balls | L1: Economy
A2: 18418557 | B2: P01 | C2: 3 | D2: 0 | E2: 23 | F2: 0 | G2: 8 | H2: 3 | I2: 0 | J2: 3 | K2: 0
A3: 18418557 | B3: P02 | C3: 4 | D3: 0 | E3: 43 | F3: 1 | G3: 11 | H3: 6 | I3: 2 | J3: 0 | K3: 1
A4: 18418557 | B4: P03 | C4: 3 | D4: 0 | E4: 29 | F4: 0 | G4: 10 | H4: 4 | I4: 1 | J4: 4 | K4: 0
A5: 18418557 | B5: P05 | C5: 2 | D5: 0 | E5: 32 | F5: 0 | G5: 4 | H5: 5 | I5: 1 | J5: 3 | K5: 0
A6: 18418557 | B6: P06 | C6: 1 | D6: 0 | E6: 9 | F6: 0 | G6: 2 | H6: 1 | I6: 0 | J6: 0 | K6: 1
A7: 18418557 | B7: P07 | C7: 2 | D7: 0 | E7: 17 | F7: 1 | G7: 3 | H7: 2 | I7: 0 | J7: 1 | K7: 0
A8: 18418557 | B8: P08 | C8: 3 | D8: 0 | E8: 42 | F8: 1 | G8: 8 | H8: 4 | I8: 2 | J8: 7 | K8: 1
A9: 18418557 | B9: P09 | C9: 3 | D9: 0 | E9: 45 | F9: 0 | G9: 5 | H9: 4 | I9: 3 | J9: 1 | K9: 2
A10: 18418557 | B10: P11 | C10: 2 | D10: 0 | E10: 22 | F10: 0 | G10: 2 | H10: 2 | I10: 0 | J10: 2 | K10: 0
A11: 18642464 | B11: P14 | C11: 6 | D11: 0 | E11: 59 | F11: 1 | G11: 18 | H11: 9 | I11: 0 | J11: 8 | K11: 2
A12: 18642464 | B12: P03 | C12: 2 | D12: 0 | E12: 27 | F12: 1 | G12: 6 | H12: 3 | I12: 1 | J12: 5 | K12: 0
A13: 18642464 | B13: P09 | C13: 6 | D13: 0 | E13: 33 | F13: 1 | G13: 18 | H13: 3 | I13: 0 | J13: 4 | K13: 0
... A32: 19112746 | B32: P18 | C32: 5.4 | D32: 0 | E32: 32 | F32: 3 | G32: 19 | H32: 2 | I32: 0 | J32: 6 | K32: 1
A33: 19859354 | B33: P03 | C33: 3 | D33: 0 | E33: 26 | F33: 2
A34: 19859354 | B34: P09 | C34: 3 | D34: 0 | E34: 20 | F34: 0
A35: 19859354 | B35: P14 | C35: 2 | D35: 0 | E35: 33 | F35: 0
A36: 19859354 | B36: P18 | C36: 3 | D36: 0 | E36: 30 | F36: 1
A37: 19859354 | B37: P04 | C37: 5 | D37: 0 | E37: 44 | F37: 2
A38: 19859354 | B38: P01 | C38: 4 | D38: 0 | E38: 44 | F38: 0
A39: 19859354 | B39: P13 | C39: 1 | D39: 0 | E39: 9 | F39: 0
A40: 13848394 | B40: P14 | C40: 3 | D40: 0 | E40: 23 | F40: 2
A41: 13848394 | B41: P02 | C41: 3 | D41: 0 | E41: 22 | F41: 2
A42: 13848394 | B42: P03 | C42: 2 | D42: 0 | E42: 9 | F42: 0
A43: 13848394 | B43: P09 | C43: 3 | D43: 0 | E43: 18 | F43: 3
A44: 13848394 | B44: P04 | C44: 5 | D44: 0 | E44: 20 | F44: 1
... A46: 13848394 | B46: P18 | C46: 4 | D46: 0 | E46: 24 | F46: 0
A47: 19989363 | B47: P03 | C47: 3 | D47: 0 | E47: 13 | F47: 0 | G47: 12 | H47: 0 | I47: 0 | J47: 5 | K47: 1
A48: 19989363 | B48: P14 | C48: 3 | D48: 1 | E48: 5 | F48: 6 | G48: 15 | H48: 0 | I48: 0 | J48: 2 | K48: 0
A49: 19989363 | B49: P08 | C49: 5 | D49: 0 | E49: 31 | F49: 1 | G49: 15 | H49: 0 | I49: 1 | J49: 7 | K49: 2
A50: 19989363 | B50: P22 | C50: 2 | D50: 0 | E50: 13 | F50: 0 | G50: 9 | H50: 0 | I50: 1 | J50: 3 | K50: 0
A51: 19989363 | B51: P15 | C51: 2 | D51: 0 | E51: 17 | F51: 1 | G51: 6 | H51: 1 | I51: 0 | J51: 6 | K51: 0
A52: 19989363 | B52: P02 | C52: 0.4 | D52: 0 | E52: 1 | F52: 1 | G52: 4 | H52: 0 | I52: 0 | J52: 1 | K52: 0
A53: 20648752 | B53: P14 | C53: 3 | D53: 0 | E53: 22 | F53: 0 | G53: 11 | H53: 2 | I53: 0 | J53: 7 | K53: 0
A54: 20648752 | B54: P25 | C54: 2 | D54: 0 | E54: 27 | F54: 0 | G54: 5 | H54: 6 | I54: 0 | J54: 2 | K54: 0
A55: 20648752 | B55: P23 | C55: 4 | D55: 0 | E55: 16 | F55: 3 | G55: 15 | H55: 2 | I55: 0 | J55: 0 | K55: 0
A56: 20648752 | B56: P09 | C56: 2 | D56: 0 | E56: 10 | F56: 0 | G56: 8 | H56: 2 | I56: 0 | J56: 0 | K56: 0
A57: 20648752 | B57: P04 | C57: 3 | D57: 0 | E57: 31 | F57: 0 | G57: 7 | H57: 2 | I57: 2 | J57: 4 | K57: 0
A58: 20648752 | B58: P01 | C58: 2.5 | D58: 0 | E58: 26 | F58: 0 | G58: 7 | H58: 3 | I58: 1 | J58: 0 | K58: 1
... A65: 20156519 | B65: P03 | C65: 0.1 | D65: 0 | E65: 1 | F65: 0 | G65: 1 | H65: 0 | I65: 0 | J65: 1 | K65: 0

Sheet Fielding
A1: MatchID | B1: PlayerID | C1: Catches | D1: Run Outs | E1: Stumpings
A2: 18418557 | B2: P02 | C2: 1 | D2: 0 | E2: 0
A3: 18418557 | B3: P06 | C3: 2 | D3: 0 | E3: 0
A4: 18642464 | B4: P01 | C4: 2 | D4: 0 | E4: 0
A5: 18642464 | B5: P15 | C5: 1 | D5: 0 | E5: 0
A6: 18642464 | B6: P06 | C6: 1 | D6: 0 | E6: 0
A7: 18642464 | B7: P09 | C7: 1 | D7: 0 | E7: 0
A8: 19019010 | B8: P18 | C8: 3 | D8: 0 | E8: 0
A9: 19019010 | B9: P16 | C9: 1 | D9: 0 | E9: 0
A10: 19019010 | B10: P04 | C10: 1 | D10: 0 | E10: 0
A11: 19019010 | B11: P01 | C11: 1 | D11: 0 | E11: 0
A12: 19112746 | B12: P01 | C12: 2 | D12: 0 | E12: 0
A13: 19112746 | B13: P08 | C13: 1 | D13: 0 | E13: 0
... A30: 20156519 | B30: P04 | C30: 1 | D30: 0 | E30: 0

Sheet Player_Career_Stats
A1: PlayerID | B1: Player Name | C1: Matches | D1: Innings | E1: Not Outs | F1: Runs | G1: Balls | H1: Fours | I1: Sixes | J1: Avg | K1: SR | L1: Balls Bowled | M1: Overs | N1: Bowl Runs | O1: Wkts | P1: Econ | Q1: Dot Balls | R1: Maidens | S1: Wides | T1: No-Balls | U1: Fours Conceded | V1: Sixes Conceded | W1: Catches | X1: Run Outs | Y1: Stumpings
A2: =IFERROR(__xludf.DUMMYFUNCTION("FILTER(Players!A2:A1000, Players!A2:A1000<>"""") "),"P01") -> P01 | B2: {=IF(A2="","",XLOOKUP(A2,Players!A:A,Players!B:B,""))} -> Sriram A | C2: =IF(A2="","", MAX( COUNTIF(Batting!B:B,A2), COUNTIF(Bowling!B:B,A2), COUNTIF(Fielding!B:B,A2) )) -> 9 | D2: =IF($A2="","",COUNTIF(Batting!$B:$B,$A2)) -> 9 | E2: =IF($A2="","",COUNTIFS(Batting!$B:$B,$A2,Batting!$G:$G,"No")) -> 0 | F2: =IF($A2="","",SUMIF(Batting!$B:$B,$A2,Batting!$C:$C)) -> 249 | G2: =IF($A2="","",SUMIF(Batting!$B:$B,$A2,Batting!$D:$D)) -> 212 | H2: =IF($A2="","",SUMIF(Batting!$B:$B,$A2,Batting!$E:$E)) -> 28 | I2: =IF($A2="","",SUMIF(Batting!$B:$B,$A2,Batting!$F:$F)) -> 2 | J2: =IF($A2="","",IF(($D2-$E2)=0,"-",ROUND($F2/($D2-$E2),2))) -> 27.67 | K2: =IF($A2="","",IF($G2=0,0,ROUND(($F2/$G2)*100,2))) -> 117.45 | L2: {=IF($A2="","", SUM( IF(Bowling!$B$2:$B1000=$A2, (INT(Bowling!$C$2:$C1000)*6) + ROUND((Bowling!$C$2:$C1000-INT(Bowling!$C$2:$C1000))*10,0), 0 ) ))} -> 179 | M2: =IF($A2="","",INT($L2/6) + MOD($L2,6)/10) -> 29.5 | N2: =IF($A2="","",SUMIF(Bowling!$B:$B,$A2,Bowling!$E:$E)) -> 218 | O2: =IF($A2="","",SUMIF(Bowling!$B:$B,$A2,Bowling!$F:$F)) -> 4 | P2: =IF($A2="","",IF($L2=0,0,ROUND($N2/($L2/6),2))) -> 7.31 | Q2: =IF($A2="","",SUMIF(Bowling!$B:$B,$A2,Bowling!$G:$G)) -> 69 | R2: =IF($A2="","",SUMIF(Bowling!$B:$B,$A2,Bowling!$D:$D)) -> 1 | S2: =IF($A2="","",SUMIF(Bowling!$B:$B,$A2,Bowling!$J:$J)) -> 10 | T2: =IF($A2="","",SUMIF(Bowling!$B:$B,$A2,Bowling!$K:$K)) -> 2 | U2: =IF($A2="","",SUMIF(Bowling!$B:$B,$A2,Bowling!$H:$H)) -> 11 | V2: =IF($A2="","",SUMIF(Bowling!$B:$B,$A2,Bowling!$I:$I)) -> 4 | W2: =IF($A2="","",SUMIF(Fielding!$B:$B,$A2,Fielding!$C:$C)) -> 8 | X2: =IF($A2="","",SUMIF(Fielding!$B:$B,$A2,Fielding!$D:$D)) -> 0 | Y2: =IF($A2="","",SUMIF(Fielding!$B:$B,$A2,Fielding!$E:$E)) -> 0
A3: =IFERROR(__xludf.DUMMYFUNCTION("""COMPUTED_VALUE"""),"P02") -> P02 | B3: {=IF(A3="","",XLOOKUP(A3,Players!A:A,Players!B:B,""))} -> Gautam Raj | C3: =IF(A3="","", MAX( COUNTIF(Batting!B:B,A3), COUNTIF(Bowling!B:B,A3), COUNTIF(Fielding!B:B,A3) )) -> 3 | D3: =IF($A3="","",COUNTIF(Batting!$B:$B,$A3)) -> 3 | E3: =IF($A3="","",COUNTIFS(Batting!$B:$B,$A3,Batting!$G:$G,"No")) -> 0 | F3: =IF($A3="","",SUMIF(Batting!$B:$B,$A3,Batting!$C:$C)) -> 4 | G3: =IF($A3="","",SUMIF(Batting!$B:$B,$A3,Batting!$D:$D)) -> 20 | H3: =IF($A3="","",SUMIF(Batting!$B:$B,$A3,Batting!$E:$E)) -> 0 | I3: =IF($A3="","",SUMIF(Batting!$B:$B,$A3,Batting!$F:$F)) -> 0 | J3: =IF($A3="","",IF(($D3-$E3)=0,"-",ROUND($F3/($D3-$E3),2))) -> 1.33 | K3: =IF($A3="","",IF($G3=0,0,ROUND(($F3/$G3)*100,2))) -> 20 | L3: {=IF($A3="","", SUM( IF(Bowling!$B$2:$B1000=$A3, (INT(Bowling!$C$2:$C1000)*6) + ROUND((Bowling!$C$2:$C1000-INT(Bowling!$C$2:$C1000))*10,0), 0 ) ))} -> 46 | M3: =IF($A3="","",INT($L3/6) + MOD($L3,6)/10) -> 7.4 | N3: =IF($A3="","",SUMIF(Bowling!$B:$B,$A3,Bowling!$E:$E)) -> 66 | O3: =IF($A3="","",SUMIF(Bowling!$B:$B,$A3,Bowling!$F:$F)) -> 4 | P3: =IF($A3="","",IF($L3=0,0,ROUND($N3/($L3/6),2))) -> 8.61 | Q3: =IF($A3="","",SUMIF(Bowling!$B:$B,$A3,Bowling!$G:$G)) -> 15 | R3: =IF($A3="","",SUMIF(Bowling!$B:$B,$A3,Bowling!$D:$D)) -> 0 | S3: =IF($A3="","",SUMIF(Bowling!$B:$B,$A3,Bowling!$J:$J)) -> 1 | T3: =IF($A3="","",SUMIF(Bowling!$B:$B,$A3,Bowling!$K:$K)) -> 1 | U3: =IF($A3="","",SUMIF(Bowling!$B:$B,$A3,Bowling!$H:$H)) -> 6 | V3: =IF($A3="","",SUMIF(Bowling!$B:$B,$A3,Bowling!$I:$I)) -> 2 | W3: =IF($A3="","",SUMIF(Fielding!$B:$B,$A3,Fielding!$C:$C)) -> 1 | X3: =IF($A3="","",SUMIF(Fielding!$B:$B,$A3,Fielding!$D:$D)) -> 0 | Y3: =IF($A3="","",SUMIF(Fielding!$B:$B,$A3,Fielding!$E:$E)) -> 0
A4: =IFERROR(__xludf.DUMMYFUNCTION("""COMPUTED_VALUE"""),"P03") -> P03 | B4: {=IF(A4="","",XLOOKUP(A4,Players!A:A,Players!B:B,""))} -> Jai | C4: =IF(A4="","", MAX( COUNTIF(Batting!B:B,A4), COUNTIF(Bowling!B:B,A4), COUNTIF(Fielding!B:B,A4) )) -> 8 | D4: =IF($A4="","",COUNTIF(Batting!$B:$B,$A4)) -> 8 | E4: =IF($A4="","",COUNTIFS(Batting!$B:$B,$A4,Batting!$G:$G,"No")) -> 2 | F4: =IF($A4="","",SUMIF(Batting!$B:$B,$A4,Batting!$C:$C)) -> 85 | G4: =IF($A4="","",SUMIF(Batting!$B:$B,$A4,Batting!$D:$D)) -> 113 | H4: =IF($A4="","",SUMIF(Batting!$B:$B,$A4,Batting!$E:$E)) -> 13 | I4: =IF($A4="","",SUMIF(Batting!$B:$B,$A4,Batting!$F:$F)) -> 0 | J4: =IF($A4="","",IF(($D4-$E4)=0,"-",ROUND($F4/($D4-$E4),2))) -> 14.17 | K4: =IF($A4="","",IF($G4=0,0,ROUND(($F4/$G4)*100,2))) -> 75.22 | L4: {=IF($A4="","", SUM( IF(Bowling!$B$2:$B1000=$A4, (INT(Bowling!$C$2:$C1000)*6) + ROUND((Bowling!$C$2:$C1000-INT(Bowling!$C$2:$C1000))*10,0), 0 ) ))} -> 91 | M4: =IF($A4="","",INT($L4/6) + MOD($L4,6)/10) -> 15.1 | N4: =IF($A4="","",SUMIF(Bowling!$B:$B,$A4,Bowling!$E:$E)) -> 123 | O4: =IF($A4="","",SUMIF(Bowling!$B:$B,$A4,Bowling!$F:$F)) -> 4 | P4: =IF($A4="","",IF($L4=0,0,ROUND($N4/($L4/6),2))) -> 8.11 | Q4: =IF($A4="","",SUMIF(Bowling!$B:$B,$A4,Bowling!$G:$G)) -> 33 | R4: =IF($A4="","",SUMIF(Bowling!$B:$B,$A4,Bowling!$D:$D)) -> 0 | S4: =IF($A4="","",SUMIF(Bowling!$B:$B,$A4,Bowling!$J:$J)) -> 19 | T4: =IF($A4="","",SUMIF(Bowling!$B:$B,$A4,Bowling!$K:$K)) -> 2 | U4: =IF($A4="","",SUMIF(Bowling!$B:$B,$A4,Bowling!$H:$H)) -> 8 | V4: =IF($A4="","",SUMIF(Bowling!$B:$B,$A4,Bowling!$I:$I)) -> 2 | W4: =IF($A4="","",SUMIF(Fielding!$B:$B,$A4,Fielding!$C:$C)) -> 1 | X4: =IF($A4="","",SUMIF(Fielding!$B:$B,$A4,Fielding!$D:$D)) -> 1 | Y4: =IF($A4="","",SUMIF(Fielding!$B:$B,$A4,Fielding!$E:$E)) -> 0
A5: =IFERROR(__xludf.DUMMYFUNCTION("""COMPUTED_VALUE"""),"P04") -> P04 | B5: {=IF(A5="","",XLOOKUP(A5,Players!A:A,Players!B:B,""))} -> Jeeva | C5: =IF(A5="","", MAX( COUNTIF(Batting!B:B,A5), COUNTIF(Bowling!B:B,A5), COUNTIF(Fielding!B:B,A5) )) -> 9 | D5: =IF($A5="","",COUNTIF(Batting!$B:$B,$A5)) -> 9 | E5: =IF($A5="","",COUNTIFS(Batting!$B:$B,$A5,Batting!$G:$G,"No")) -> 1 | F5: =IF($A5="","",SUMIF(Batting!$B:$B,$A5,Batting!$C:$C)) -> 163 | G5: =IF($A5="","",SUMIF(Batting!$B:$B,$A5,Batting!$D:$D)) -> 147 | H5: =IF($A5="","",SUMIF(Batting!$B:$B,$A5,Batting!$E:$E)) -> 15 | I5: =IF($A5="","",SUMIF(Batting!$B:$B,$A5,Batting!$F:$F)) -> 7 | J5: =IF($A5="","",IF(($D5-$E5)=0,"-",ROUND($F5/($D5-$E5),2))) -> 20.38 | K5: =IF($A5="","",IF($G5=0,0,ROUND(($F5/$G5)*100,2))) -> 110.88 | L5: {=IF($A5="","", SUM( IF(Bowling!$B$2:$B1000=$A5, (INT(Bowling!$C$2:$C1000)*6) + ROUND((Bowling!$C$2:$C1000-INT(Bowling!$C$2:$C1000))*10,0), 0 ) ))} -> 210 | M5: =IF($A5="","",INT($L5/6) + MOD($L5,6)/10) -> 35 | N5: =IF($A5="","",SUMIF(Bowling!$B:$B,$A5,Bowling!$E:$E)) -> 243 | O5: =IF($A5="","",SUMIF(Bowling!$B:$B,$A5,Bowling!$F:$F)) -> 11 | P5: =IF($A5="","",IF($L5=0,0,ROUND($N5/($L5/6),2))) -> 6.94 | Q5: =IF($A5="","",SUMIF(Bowling!$B:$B,$A5,Bowling!$G:$G)) -> 76 | R5: =IF($A5="","",SUMIF(Bowling!$B:$B,$A5,Bowling!$D:$D)) -> 0 | S5: =IF($A5="","",SUMIF(Bowling!$B:$B,$A5,Bowling!$J:$J)) -> 21 | T5: =IF($A5="","",SUMIF(Bowling!$B:$B,$A5,Bowling!$K:$K)) -> 3 | U5: =IF($A5="","",SUMIF(Bowling!$B:$B,$A5,Bowling!$H:$H)) -> 21 | V5: =IF($A5="","",SUMIF(Bowling!$B:$B,$A5,Bowling!$I:$I)) -> 2 | W5: =IF($A5="","",SUMIF(Fielding!$B:$B,$A5,Fielding!$C:$C)) -> 5 | X5: =IF($A5="","",SUMIF(Fielding!$B:$B,$A5,Fielding!$D:$D)) -> 0 | Y5: =IF($A5="","",SUMIF(Fielding!$B:$B,$A5,Fielding!$E:$E)) -> 0
A6: =IFERROR(__xludf.DUMMYFUNCTION("""COMPUTED_VALUE"""),"P05") -> P05 | B6: {=IF(A6="","",XLOOKUP(A6,Players!A:A,Players!B:B,""))} -> Naveen | C6: =IF(A6="","", MAX( COUNTIF(Batting!B:B,A6), COUNTIF(Bowling!B:B,A6), COUNTIF(Fielding!B:B,A6) )) -> 1 | D6: =IF($A6="","",COUNTIF(Batting!$B:$B,$A6)) -> 1 | E6: =IF($A6="","",COUNTIFS(Batting!$B:$B,$A6,Batting!$G:$G,"No")) -> 0 | F6: =IF($A6="","",SUMIF(Batting!$B:$B,$A6,Batting!$C:$C)) -> 4 | G6: =IF($A6="","",SUMIF(Batting!$B:$B,$A6,Batting!$D:$D)) -> 6 | H6: =IF($A6="","",SUMIF(Batting!$B:$B,$A6,Batting!$E:$E)) -> 1 | I6: =IF($A6="","",SUMIF(Batting!$B:$B,$A6,Batting!$F:$F)) -> 0 | J6: =IF($A6="","",IF(($D6-$E6)=0,"-",ROUND($F6/($D6-$E6),2))) -> 4 | K6: =IF($A6="","",IF($G6=0,0,ROUND(($F6/$G6)*100,2))) -> 66.67 | L6: {=IF($A6="","", SUM( IF(Bowling!$B$2:$B1000=$A6, (INT(Bowling!$C$2:$C1000)*6) + ROUND((Bowling!$C$2:$C1000-INT(Bowling!$C$2:$C1000))*10,0), 0 ) ))} -> 12 | M6: =IF($A6="","",INT($L6/6) + MOD($L6,6)/10) -> 2 | N6: =IF($A6="","",SUMIF(Bowling!$B:$B,$A6,Bowling!$E:$E)) -> 32 | O6: =IF($A6="","",SUMIF(Bowling!$B:$B,$A6,Bowling!$F:$F)) -> 0 | P6: =IF($A6="","",IF($L6=0,0,ROUND($N6/($L6/6),2))) -> 16 | Q6: =IF($A6="","",SUMIF(Bowling!$B:$B,$A6,Bowling!$G:$G)) -> 4 | R6: =IF($A6="","",SUMIF(Bowling!$B:$B,$A6,Bowling!$D:$D)) -> 0 | S6: =IF($A6="","",SUMIF(Bowling!$B:$B,$A6,Bowling!$J:$J)) -> 3 | T6: =IF($A6="","",SUMIF(Bowling!$B:$B,$A6,Bowling!$K:$K)) -> 0 | U6: =IF($A6="","",SUMIF(Bowling!$B:$B,$A6,Bowling!$H:$H)) -> 5 | V6: =IF($A6="","",SUMIF(Bowling!$B:$B,$A6,Bowling!$I:$I)) -> 1 | W6: =IF($A6="","",SUMIF(Fielding!$B:$B,$A6,Fielding!$C:$C)) -> 0 | X6: =IF($A6="","",SUMIF(Fielding!$B:$B,$A6,Fielding!$D:$D)) -> 0 | Y6: =IF($A6="","",SUMIF(Fielding!$B:$B,$A6,Fielding!$E:$E)) -> 0
A7: =IFERROR(__xludf.DUMMYFUNCTION("""COMPUTED_VALUE"""),"P06") -> P06 | B7: {=IF(A7="","",XLOOKUP(A7,Players!A:A,Players!B:B,""))} -> Sanjay V | C7: =IF(A7="","", MAX( COUNTIF(Batting!B:B,A7), COUNTIF(Bowling!B:B,A7), COUNTIF(Fielding!B:B,A7) )) -> 6 | D7: =IF($A7="","",COUNTIF(Batting!$B:$B,$A7)) -> 6 | E7: =IF($A7="","",COUNTIFS(Batting!$B:$B,$A7,Batting!$G:$G,"No")) -> 0 | F7: =IF($A7="","",SUMIF(Batting!$B:$B,$A7,Batting!$C:$C)) -> 119 | G7: =IF($A7="","",SUMIF(Batting!$B:$B,$A7,Batting!$D:$D)) -> 117 | H7: =IF($A7="","",SUMIF(Batting!$B:$B,$A7,Batting!$E:$E)) -> 19 | I7: =IF($A7="","",SUMIF(Batting!$B:$B,$A7,Batting!$F:$F)) -> 1 | J7: =IF($A7="","",IF(($D7-$E7)=0,"-",ROUND($F7/($D7-$E7),2))) -> 19.83 | K7: =IF($A7="","",IF($G7=0,0,ROUND(($F7/$G7)*100,2))) -> 101.71 | L7: {=IF($A7="","", SUM( IF(Bowling!$B$2:$B1000=$A7, (INT(Bowling!$C$2:$C1000)*6) + ROUND((Bowling!$C$2:$C1000-INT(Bowling!$C$2:$C1000))*10,0), 0 ) ))} -> 12 | M7: =IF($A7="","",INT($L7/6) + MOD($L7,6)/10) -> 2 | N7: =IF($A7="","",SUMIF(Bowling!$B:$B,$A7,Bowling!$E:$E)) -> 24 | O7: =IF($A7="","",SUMIF(Bowling!$B:$B,$A7,Bowling!$F:$F)) -> 0 | P7: =IF($A7="","",IF($L7=0,0,ROUND($N7/($L7/6),2))) -> 12 | Q7: =IF($A7="","",SUMIF(Bowling!$B:$B,$A7,Bowling!$G:$G)) -> 3 | R7: =IF($A7="","",SUMIF(Bowling!$B:$B,$A7,Bowling!$D:$D)) -> 0 | S7: =IF($A7="","",SUMIF(Bowling!$B:$B,$A7,Bowling!$J:$J)) -> 0 | T7: =IF($A7="","",SUMIF(Bowling!$B:$B,$A7,Bowling!$K:$K)) -> 1 | U7: =IF($A7="","",SUMIF(Bowling!$B:$B,$A7,Bowling!$H:$H)) -> 4 | V7: =IF($A7="","",SUMIF(Bowling!$B:$B,$A7,Bowling!$I:$I)) -> 0 | W7: =IF($A7="","",SUMIF(Fielding!$B:$B,$A7,Fielding!$C:$C)) -> 4 | X7: =IF($A7="","",SUMIF(Fielding!$B:$B,$A7,Fielding!$D:$D)) -> 0 | Y7: =IF($A7="","",SUMIF(Fielding!$B:$B,$A7,Fielding!$E:$E)) -> 0
A8: =IFERROR(__xludf.DUMMYFUNCTION("""COMPUTED_VALUE"""),"P07") -> P07 | B8: {=IF(A8="","",XLOOKUP(A8,Players!A:A,Players!B:B,""))} -> Saravanan G | C8: =IF(A8="","", MAX( COUNTIF(Batting!B:B,A8), COUNTIF(Bowling!B:B,A8), COUNTIF(Fielding!B:B,A8) )) -> 7 | D8: =IF($A8="","",COUNTIF(Batting!$B:$B,$A8)) -> 7 | E8: =IF($A8="","",COUNTIFS(Batting!$B:$B,$A8,Batting!$G:$G,"No")) -> 1 | F8: =IF($A8="","",SUMIF(Batting!$B:$B,$A8,Batting!$C:$C)) -> 55 | G8: =IF($A8="","",SUMIF(Batting!$B:$B,$A8,Batting!$D:$D)) -> 79 | H8: =IF($A8="","",SUMIF(Batting!$B:$B,$A8,Batting!$E:$E)) -> 4 | I8: =IF($A8="","",SUMIF(Batting!$B:$B,$A8,Batting!$F:$F)) -> 0 | J8: =IF($A8="","",IF(($D8-$E8)=0,"-",ROUND($F8/($D8-$E8),2))) -> 9.17 | K8: =IF($A8="","",IF($G8=0,0,ROUND(($F8/$G8)*100,2))) -> 69.62 | L8: {=IF($A8="","", SUM( IF(Bowling!$B$2:$B1000=$A8, (INT(Bowling!$C$2:$C1000)*6) + ROUND((Bowling!$C$2:$C1000-INT(Bowling!$C$2:$C1000))*10,0), 0 ) ))} -> 12 | M8: =IF($A8="","",INT($L8/6) + MOD($L8,6)/10) -> 2 | N8: =IF($A8="","",SUMIF(Bowling!$B:$B,$A8,Bowling!$E:$E)) -> 17 | O8: =IF($A8="","",SUMIF(Bowling!$B:$B,$A8,Bowling!$F:$F)) -> 1 | P8: =IF($A8="","",IF($L8=0,0,ROUND($N8/($L8/6),2))) -> 8.5 | Q8: =IF($A8="","",SUMIF(Bowling!$B:$B,$A8,Bowling!$G:$G)) -> 3 | R8: =IF($A8="","",SUMIF(Bowling!$B:$B,$A8,Bowling!$D:$D)) -> 0 | S8: =IF($A8="","",SUMIF(Bowling!$B:$B,$A8,Bowling!$J:$J)) -> 1 | T8: =IF($A8="","",SUMIF(Bowling!$B:$B,$A8,Bowling!$K:$K)) -> 0 | U8: =IF($A8="","",SUMIF(Bowling!$B:$B,$A8,Bowling!$H:$H)) -> 2 | V8: =IF($A8="","",SUMIF(Bowling!$B:$B,$A8,Bowling!$I:$I)) -> 0 | W8: =IF($A8="","",SUMIF(Fielding!$B:$B,$A8,Fielding!$C:$C)) -> 1 | X8: =IF($A8="","",SUMIF(Fielding!$B:$B,$A8,Fielding!$D:$D)) -> 0 | Y8: =IF($A8="","",SUMIF(Fielding!$B:$B,$A8,Fielding!$E:$E)) -> 0
A9: =IFERROR(__xludf.DUMMYFUNCTION("""COMPUTED_VALUE"""),"P08") -> P08 | B9: {=IF(A9="","",XLOOKUP(A9,Players!A:A,Players!B:B,""))} -> Senthil kumar | C9: =IF(A9="","", MAX( COUNTIF(Batting!B:B,A9), COUNTIF(Bowling!B:B,A9), COUNTIF(Fielding!B:B,A9) )) -> 4 | D9: =IF($A9="","",COUNTIF(Batting!$B:$B,$A9)) -> 4 | E9: =IF($A9="","",COUNTIFS(Batting!$B:$B,$A9,Batting!$G:$G,"No")) -> 1 | F9: =IF($A9="","",SUMIF(Batting!$B:$B,$A9,Batting!$C:$C)) -> 18 | G9: =IF($A9="","",SUMIF(Batting!$B:$B,$A9,Batting!$D:$D)) -> 35 | H9: =IF($A9="","",SUMIF(Batting!$B:$B,$A9,Batting!$E:$E)) -> 2 | I9: =IF($A9="","",SUMIF(Batting!$B:$B,$A9,Batting!$F:$F)) -> 0 | J9: =IF($A9="","",IF(($D9-$E9)=0,"-",ROUND($F9/($D9-$E9),2))) -> 6 | K9: =IF($A9="","",IF($G9=0,0,ROUND(($F9/$G9)*100,2))) -> 51.43 | L9: {=IF($A9="","", SUM( IF(Bowling!$B$2:$B1000=$A9, (INT(Bowling!$C$2:$C1000)*6) + ROUND((Bowling!$C$2:$C1000-INT(Bowling!$C$2:$C1000))*10,0), 0 ) ))} -> 54 | M9: =IF($A9="","",INT($L9/6) + MOD($L9,6)/10) -> 9 | N9: =IF($A9="","",SUMIF(Bowling!$B:$B,$A9,Bowling!$E:$E)) -> 91 | O9: =IF($A9="","",SUMIF(Bowling!$B:$B,$A9,Bowling!$F:$F)) -> 2 | P9: =IF($A9="","",IF($L9=0,0,ROUND($N9/($L9/6),2))) -> 10.11 | Q9: =IF($A9="","",SUMIF(Bowling!$B:$B,$A9,Bowling!$G:$G)) -> 24 | R9: =IF($A9="","",SUMIF(Bowling!$B:$B,$A9,Bowling!$D:$D)) -> 0 | S9: =IF($A9="","",SUMIF(Bowling!$B:$B,$A9,Bowling!$J:$J)) -> 15 | T9: =IF($A9="","",SUMIF(Bowling!$B:$B,$A9,Bowling!$K:$K)) -> 3 | U9: =IF($A9="","",SUMIF(Bowling!$B:$B,$A9,Bowling!$H:$H)) -> 6 | V9: =IF($A9="","",SUMIF(Bowling!$B:$B,$A9,Bowling!$I:$I)) -> 4 | W9: =IF($A9="","",SUMIF(Fielding!$B:$B,$A9,Fielding!$C:$C)) -> 1 | X9: =IF($A9="","",SUMIF(Fielding!$B:$B,$A9,Fielding!$D:$D)) -> 0 | Y9: =IF($A9="","",SUMIF(Fielding!$B:$B,$A9,Fielding!$E:$E)) -> 0
A10: =IFERROR(__xludf.DUMMYFUNCTION("""COMPUTED_VALUE"""),"P09") -> P09 | B10: {=IF(A10="","",XLOOKUP(A10,Players!A:A,Players!B:B,""))} -> Shivaganesh | C10: =IF(A10="","", MAX( COUNTIF(Batting!B:B,A10), COUNTIF(Bowling!B:B,A10), COUNTIF(Fielding!B:B,A10) )) -> 9 | D10: =IF($A10="","",COUNTIF(Batting!$B:$B,$A10)) -> 9 | E10: =IF($A10="","",COUNTIFS(Batting!$B:$B,$A10,Batting!$G:$G,"No")) -> 2 | F10: =IF($A10="","",SUMIF(Batting!$B:$B,$A10,Batting!$C:$C)) -> 146 | G10: =IF($A10="","",SUMIF(Batting!$B:$B,$A10,Batting!$D:$D)) -> 187 | H10: =IF($A10="","",SUMIF(Batting!$B:$B,$A10,Batting!$E:$E)) -> 17 | I10: =IF($A10="","",SUMIF(Batting!$B:$B,$A10,Batting!$F:$F)) -> 1 | J10: =IF($A10="","",IF(($D10-$E10)=0,"-",ROUND($F10/($D10-$E10),2))) -> 20.86 | K10: =IF($A10="","",IF($G10=0,0,ROUND(($F10/$G10)*100,2))) -> 78.07 | L10: {=IF($A10="","", SUM( IF(Bowling!$B$2:$B1000=$A10, (INT(Bowling!$C$2:$C1000)*6) + ROUND((Bowling!$C$2:$C1000-INT(Bowling!$C$2:$C1000))*10,0), 0 ) ))} -> 162 | M10: =IF($A10="","",INT($L10/6) + MOD($L10,6)/10) -> 27 | N10: =IF($A10="","",SUMIF(Bowling!$B:$B,$A10,Bowling!$E:$E)) -> 209 | O10: =IF($A10="","",SUMIF(Bowling!$B:$B,$A10,Bowling!$F:$F)) -> 6 | P10: =IF($A10="","",IF($L10=0,0,ROUND($N10/($L10/6),2))) -> 7.74 | Q10: =IF($A10="","",SUMIF(Bowling!$B:$B,$A10,Bowling!$G:$G)) -> 56 | R10: =IF($A10="","",SUMIF(Bowling!$B:$B,$A10,Bowling!$D:$D)) -> 0 | S10: =IF($A10="","",SUMIF(Bowling!$B:$B,$A10,Bowling!$J:$J)) -> 7 | T10: =IF($A10="","",SUMIF(Bowling!$B:$B,$A10,Bowling!$K:$K)) -> 2 | U10: =IF($A10="","",SUMIF(Bowling!$B:$B,$A10,Bowling!$H:$H)) -> 21 | V10: =IF($A10="","",SUMIF(Bowling!$B:$B,$A10,Bowling!$I:$I)) -> 4 | W10: =IF($A10="","",SUMIF(Fielding!$B:$B,$A10,Fielding!$C:$C)) -> 3 | X10: =IF($A10="","",SUMIF(Fielding!$B:$B,$A10,Fielding!$D:$D)) -> 0 | Y10: =IF($A10="","",SUMIF(Fielding!$B:$B,$A10,Fielding!$E:$E)) -> 0
A11: =IFERROR(__xludf.DUMMYFUNCTION("""COMPUTED_VALUE"""),"P10") -> P10 | B11: {=IF(A11="","",XLOOKUP(A11,Players!A:A,Players!B:B,""))} -> Tharun M | C11: =IF(A11="","", MAX( COUNTIF(Batting!B:B,A11), COUNTIF(Bowling!B:B,A11), COUNTIF(Fielding!B:B,A11) )) -> 5 | D11: =IF($A11="","",COUNTIF(Batting!$B:$B,$A11)) -> 5 | E11: =IF($A11="","",COUNTIFS(Batting!$B:$B,$A11,Batting!$G:$G,"No")) -> 0 | F11: =IF($A11="","",SUMIF(Batting!$B:$B,$A11,Batting!$C:$C)) -> 20 | G11: =IF($A11="","",SUMIF(Batting!$B:$B,$A11,Batting!$D:$D)) -> 24 | H11: =IF($A11="","",SUMIF(Batting!$B:$B,$A11,Batting!$E:$E)) -> 1 | I11: =IF($A11="","",SUMIF(Batting!$B:$B,$A11,Batting!$F:$F)) -> 0 | J11: =IF($A11="","",IF(($D11-$E11)=0,"-",ROUND($F11/($D11-$E11),2))) -> 4 | K11: =IF($A11="","",IF($G11=0,0,ROUND(($F11/$G11)*100,2))) -> 83.33 | L11: {=IF($A11="","", SUM( IF(Bowling!$B$2:$B1000=$A11, (INT(Bowling!$C$2:$C1000)*6) + ROUND((Bowling!$C$2:$C1000-INT(Bowling!$C$2:$C1000))*10,0), 0 ) ))} -> 0 | M11: =IF($A11="","",INT($L11/6) + MOD($L11,6)/10) -> 0 | N11: =IF($A11="","",SUMIF(Bowling!$B:$B,$A11,Bowling!$E:$E)) -> 0 | O11: =IF($A11="","",SUMIF(Bowling!$B:$B,$A11,Bowling!$F:$F)) -> 0 | P11: =IF($A11="","",IF($L11=0,0,ROUND($N11/($L11/6),2))) -> 0 | Q11: =IF($A11="","",SUMIF(Bowling!$B:$B,$A11,Bowling!$G:$G)) -> 0 | R11: =IF($A11="","",SUMIF(Bowling!$B:$B,$A11,Bowling!$D:$D)) -> 0 | S11: =IF($A11="","",SUMIF(Bowling!$B:$B,$A11,Bowling!$J:$J)) -> 0 | T11: =IF($A11="","",SUMIF(Bowling!$B:$B,$A11,Bowling!$K:$K)) -> 0 | U11: =IF($A11="","",SUMIF(Bowling!$B:$B,$A11,Bowling!$H:$H)) -> 0 | V11: =IF($A11="","",SUMIF(Bowling!$B:$B,$A11,Bowling!$I:$I)) -> 0 | W11: =IF($A11="","",SUMIF(Fielding!$B:$B,$A11,Fielding!$C:$C)) -> 1 | X11: =IF($A11="","",SUMIF(Fielding!$B:$B,$A11,Fielding!$D:$D)) -> 0 | Y11: =IF($A11="","",SUMIF(Fielding!$B:$B,$A11,Fielding!$E:$E)) -> 1
A12: =IFERROR(__xludf.DUMMYFUNCTION("""COMPUTED_VALUE"""),"P11") -> P11 | B12: {=IF(A12="","",XLOOKUP(A12,Players!A:A,Players!B:B,""))} -> Vikram | C12: =IF(A12="","", MAX( COUNTIF(Batting!B:B,A12), COUNTIF(Bowling!B:B,A12), COUNTIF(Fielding!B:B,A12) )) -> 2 | D12: =IF($A12="","",COUNTIF(Batting!$B:$B,$A12)) -> 2 | E12: =IF($A12="","",COUNTIFS(Batting!$B:$B,$A12,Batting!$G:$G,"No")) -> 0 | F12: =IF($A12="","",SUMIF(Batting!$B:$B,$A12,Batting!$C:$C)) -> 0 | G12: =IF($A12="","",SUMIF(Batting!$B:$B,$A12,Batting!$D:$D)) -> 2 | H12: =IF($A12="","",SUMIF(Batting!$B:$B,$A12,Batting!$E:$E)) -> 0 | I12: =IF($A12="","",SUMIF(Batting!$B:$B,$A12,Batting!$F:$F)) -> 0 | J12: =IF($A12="","",IF(($D12-$E12)=0,"-",ROUND($F12/($D12-$E12),2))) -> 0 | K12: =IF($A12="","",IF($G12=0,0,ROUND(($F12/$G12)*100,2))) -> 0 | L12: {=IF($A12="","", SUM( IF(Bowling!$B$2:$B1000=$A12, (INT(Bowling!$C$2:$C1000)*6) + ROUND((Bowling!$C$2:$C1000-INT(Bowling!$C$2:$C1000))*10,0), 0 ) ))} -> 24 | M12: =IF($A12="","",INT($L12/6) + MOD($L12,6)/10) -> 4 | N12: =IF($A12="","",SUMIF(Bowling!$B:$B,$A12,Bowling!$E:$E)) -> 34 | O12: =IF($A12="","",SUMIF(Bowling!$B:$B,$A12,Bowling!$F:$F)) -> 1 | P12: =IF($A12="","",IF($L12=0,0,ROUND($N12/($L12/6),2))) -> 8.5 | Q12: =IF($A12="","",SUMIF(Bowling!$B:$B,$A12,Bowling!$G:$G)) -> 12 | R12: =IF($A12="","",SUMIF(Bowling!$B:$B,$A12,Bowling!$D:$D)) -> 0 | S12: =IF($A12="","",SUMIF(Bowling!$B:$B,$A12,Bowling!$J:$J)) -> 8 | T12: =IF($A12="","",SUMIF(Bowling!$B:$B,$A12,Bowling!$K:$K)) -> 3 | U12: =IF($A12="","",SUMIF(Bowling!$B:$B,$A12,Bowling!$H:$H)) -> 2 | V12: =IF($A12="","",SUMIF(Bowling!$B:$B,$A12,Bowling!$I:$I)) -> 0 | W12: =IF($A12="","",SUMIF(Fielding!$B:$B,$A12,Fielding!$C:$C)) -> 0 | X12: =IF($A12="","",SUMIF(Fielding!$B:$B,$A12,Fielding!$D:$D)) -> 0 | Y12: =IF($A12="","",SUMIF(Fielding!$B:$B,$A12,Fielding!$E:$E)) -> 0
A13: =IFERROR(__xludf.DUMMYFUNCTION("""COMPUTED_VALUE"""),"P12") -> P12 | B13: {=IF(A13="","",XLOOKUP(A13,Players!A:A,Players!B:B,""))} -> Mukundhan S | C13: =IF(A13="","", MAX( COUNTIF(Batting!B:B,A13), COUNTIF(Bowling!B:B,A13), COUNTIF(Fielding!B:B,A13) )) -> 1 | D13: =IF($A13="","",COUNTIF(Batting!$B:$B,$A13)) -> 1 | E13: =IF($A13="","",COUNTIFS(Batting!$B:$B,$A13,Batting!$G:$G,"No")) -> 0 | F13: =IF($A13="","",SUMIF(Batting!$B:$B,$A13,Batting!$C:$C)) -> 1 | G13: =IF($A13="","",SUMIF(Batting!$B:$B,$A13,Batting!$D:$D)) -> 5 | H13: =IF($A13="","",SUMIF(Batting!$B:$B,$A13,Batting!$E:$E)) -> 0 | I13: =IF($A13="","",SUMIF(Batting!$B:$B,$A13,Batting!$F:$F)) -> 0 | J13: =IF($A13="","",IF(($D13-$E13)=0,"-",ROUND($F13/($D13-$E13),2))) -> 1 | K13: =IF($A13="","",IF($G13=0,0,ROUND(($F13/$G13)*100,2))) -> 20 | L13: {=IF($A13="","", SUM( IF(Bowling!$B$2:$B1000=$A13, (INT(Bowling!$C$2:$C1000)*6) + ROUND((Bowling!$C$2:$C1000-INT(Bowling!$C$2:$C1000))*10,0), 0 ) ))} -> 0 | M13: =IF($A13="","",INT($L13/6) + MOD($L13,6)/10) -> 0 | N13: =IF($A13="","",SUMIF(Bowling!$B:$B,$A13,Bowling!$E:$E)) -> 0 | O13: =IF($A13="","",SUMIF(Bowling!$B:$B,$A13,Bowling!$F:$F)) -> 0 | P13: =IF($A13="","",IF($L13=0,0,ROUND($N13/($L13/6),2))) -> 0 | Q13: =IF($A13="","",SUMIF(Bowling!$B:$B,$A13,Bowling!$G:$G)) -> 0 | R13: =IF($A13="","",SUMIF(Bowling!$B:$B,$A13,Bowling!$D:$D)) -> 0 | S13: =IF($A13="","",SUMIF(Bowling!$B:$B,$A13,Bowling!$J:$J)) -> 0 | T13: =IF($A13="","",SUMIF(Bowling!$B:$B,$A13,Bowling!$K:$K)) -> 0 | U13: =IF($A13="","",SUMIF(Bowling!$B:$B,$A13,Bowling!$H:$H)) -> 0 | V13: =IF($A13="","",SUMIF(Bowling!$B:$B,$A13,Bowling!$I:$I)) -> 0 | W13: =IF($A13="","",SUMIF(Fielding!$B:$B,$A13,Fielding!$C:$C)) -> 0 | X13: =IF($A13="","",SUMIF(Fielding!$B:$B,$A13,Fielding!$D:$D)) -> 0 | Y13: =IF($A13="","",SUMIF(Fielding!$B:$B,$A13,Fielding!$E:$E)) -> 0
A14: =IFERROR(__xludf.DUMMYFUNCTION("""COMPUTED_VALUE"""),"P13") -> P13 | B14: {=IF(A14="","",XLOOKUP(A14,Players!A:A,Players!B:B,""))} -> Padhu | C14: =IF(A14="","", MAX( COUNTIF(Batting!B:B,A14), COUNTIF(Bowling!B:B,A14), COUNTIF(Fielding!B:B,A14) )) -> 3 | D14: =IF($A14="","",COUNTIF(Batting!$B:$B,$A14)) -> 3 | E14: =IF($A14="","",COUNTIFS(Batting!$B:$B,$A14,Batting!$G:$G,"No")) -> 0 | F14: =IF($A14="","",SUMIF(Batting!$B:$B,$A14,Batting!$C:$C)) -> 41 | G14: =IF($A14="","",SUMIF(Batting!$B:$B,$A14,Batting!$D:$D)) -> 36 | H14: =IF($A14="","",SUMIF(Batting!$B:$B,$A14,Batting!$E:$E)) -> 6 | I14: =IF($A14="","",SUMIF(Batting!$B:$B,$A14,Batting!$F:$F)) -> 0 | J14: =IF($A14="","",IF(($D14-$E14)=0,"-",ROUND($F14/($D14-$E14),2))) -> 13.67 | K14: =IF($A14="","",IF($G14=0,0,ROUND(($F14/$G14)*100,2))) -> 113.89 | L14: {=IF($A14="","", SUM( IF(Bowling!$B$2:$B1000=$A14, (INT(Bowling!$C$2:$C1000)*6) + ROUND((Bowling!$C$2:$C1000-INT(Bowling!$C$2:$C1000))*10,0), 0 ) ))} -> 48 | M14: =IF($A14="","",INT($L14/6) + MOD($L14,6)/10) -> 8 | N14: =IF($A14="","",SUMIF(Bowling!$B:$B,$A14,Bowling!$E:$E)) -> 59 | O14: =IF($A14="","",SUMIF(Bowling!$B:$B,$A14,Bowling!$F:$F)) -> 1 | P14: =IF($A14="","",IF($L14=0,0,ROUND($N14/($L14/6),2))) -> 7.38 | Q14: =IF($A14="","",SUMIF(Bowling!$B:$B,$A14,Bowling!$G:$G)) -> 20 | R14: =IF($A14="","",SUMIF(Bowling!$B:$B,$A14,Bowling!$D:$D)) -> 1 | S14: =IF($A14="","",SUMIF(Bowling!$B:$B,$A14,Bowling!$J:$J)) -> 12 | T14: =IF($A14="","",SUMIF(Bowling!$B:$B,$A14,Bowling!$K:$K)) -> 1 | U14: =IF($A14="","",SUMIF(Bowling!$B:$B,$A14,Bowling!$H:$H)) -> 2 | V14: =IF($A14="","",SUMIF(Bowling!$B:$B,$A14,Bowling!$I:$I)) -> 1 | W14: =IF($A14="","",SUMIF(Fielding!$B:$B,$A14,Fielding!$C:$C)) -> 0 | X14: =IF($A14="","",SUMIF(Fielding!$B:$B,$A14,Fielding!$D:$D)) -> 0 | Y14: =IF($A14="","",SUMIF(Fielding!$B:$B,$A14,Fielding!$E:$E)) -> 0
A15: =IFERROR(__xludf.DUMMYFUNCTION("""COMPUTED_VALUE"""),"P14") -> P14 | B15: {=IF(A15="","",XLOOKUP(A15,Players!A:A,Players!B:B,""))} -> Ravi Shankar | C15: =IF(A15="","", MAX( COUNTIF(Batting!B:B,A15), COUNTIF(Bowling!B:B,A15), COUNTIF(Fielding!B:B,A15) )) -> 8 | D15: =IF($A15="","",COUNTIF(Batting!$B:$B,$A15)) -> 6 | E15: =IF($A15="","",COUNTIFS(Batting!$B:$B,$A15,Batting!$G:$G,"No")) -> 4 | F15: =IF($A15="","",SUMIF(Batting!$B:$B,$A15,Batting!$C:$C)) -> 11 | G15: =IF($A15="","",SUMIF(Batting!$B:$B,$A15,Batting!$D:$D)) -> 24 | H15: =IF($A15="","",SUMIF(Batting!$B:$B,$A15,Batting!$E:$E)) -> 0 | I15: =IF($A15="","",SUMIF(Batting!$B:$B,$A15,Batting!$F:$F)) -> 0 | J15: =IF($A15="","",IF(($D15-$E15)=0,"-",ROUND($F15/($D15-$E15),2))) -> 5.5 | K15: =IF($A15="","",IF($G15=0,0,ROUND(($F15/$G15)*100,2))) -> 45.83 | L15: {=IF($A15="","", SUM( IF(Bowling!$B$2:$B1000=$A15, (INT(Bowling!$C$2:$C1000)*6) + ROUND((Bowling!$C$2:$C1000-INT(Bowling!$C$2:$C1000))*10,0), 0 ) ))} -> 179 | M15: =IF($A15="","",INT($L15/6) + MOD($L15,6)/10) -> 29.5 | N15: =IF($A15="","",SUMIF(Bowling!$B:$B,$A15,Bowling!$E:$E)) -> 232 | O15: =IF($A15="","",SUMIF(Bowling!$B:$B,$A15,Bowling!$F:$F)) -> 11 | P15: =IF($A15="","",IF($L15=0,0,ROUND($N15/($L15/6),2))) -> 7.78 | Q15: =IF($A15="","",SUMIF(Bowling!$B:$B,$A15,Bowling!$G:$G)) -> 89 | R15: =IF($A15="","",SUMIF(Bowling!$B:$B,$A15,Bowling!$D:$D)) -> 1 | S15: =IF($A15="","",SUMIF(Bowling!$B:$B,$A15,Bowling!$J:$J)) -> 34 | T15: =IF($A15="","",SUMIF(Bowling!$B:$B,$A15,Bowling!$K:$K)) -> 2 | U15: =IF($A15="","",SUMIF(Bowling!$B:$B,$A15,Bowling!$H:$H)) -> 20 | V15: =IF($A15="","",SUMIF(Bowling!$B:$B,$A15,Bowling!$I:$I)) -> 2 | W15: =IF($A15="","",SUMIF(Fielding!$B:$B,$A15,Fielding!$C:$C)) -> 0 | X15: =IF($A15="","",SUMIF(Fielding!$B:$B,$A15,Fielding!$D:$D)) -> 1 | Y15: =IF($A15="","",SUMIF(Fielding!$B:$B,$A15,Fielding!$E:$E)) -> 0
A16: =IFERROR(__xludf.DUMMYFUNCTION("""COMPUTED_VALUE"""),"P15") -> P15 | B16: {=IF(A16="","",XLOOKUP(A16,Players!A:A,Players!B:B,""))} -> Mahesh | C16: =IF(A16="","", MAX( COUNTIF(Batting!B:B,A16), COUNTIF(Bowling!B:B,A16), COUNTIF(Fielding!B:B,A16) )) -> 2 | D16: =IF($A16="","",COUNTIF(Batting!$B:$B,$A16)) -> 2 | E16: =IF($A16="","",COUNTIFS(Batting!$B:$B,$A16,Batting!$G:$G,"No")) -> 0 | F16: =IF($A16="","",SUMIF(Batting!$B:$B,$A16,Batting!$C:$C)) -> 0 | G16: =IF($A16="","",SUMIF(Batting!$B:$B,$A16,Batting!$D:$D)) -> 2 | H16: =IF($A16="","",SUMIF(Batting!$B:$B,$A16,Batting!$E:$E)) -> 0 | I16: =IF($A16="","",SUMIF(Batting!$B:$B,$A16,Batting!$F:$F)) -> 0 | J16: =IF($A16="","",IF(($D16-$E16)=0,"-",ROUND($F16/($D16-$E16),2))) -> 0 | K16: =IF($A16="","",IF($G16=0,0,ROUND(($F16/$G16)*100,2))) -> 0 | L16: {=IF($A16="","", SUM( IF(Bowling!$B$2:$B1000=$A16, (INT(Bowling!$C$2:$C1000)*6) + ROUND((Bowling!$C$2:$C1000-INT(Bowling!$C$2:$C1000))*10,0), 0 ) ))} -> 18 | M16: =IF($A16="","",INT($L16/6) + MOD($L16,6)/10) -> 3 | N16: =IF($A16="","",SUMIF(Bowling!$B:$B,$A16,Bowling!$E:$E)) -> 28 | O16: =IF($A16="","",SUMIF(Bowling!$B:$B,$A16,Bowling!$F:$F)) -> 1 | P16: =IF($A16="","",IF($L16=0,0,ROUND($N16/($L16/6),2))) -> 9.33 | Q16: =IF($A16="","",SUMIF(Bowling!$B:$B,$A16,Bowling!$G:$G)) -> 9 | R16: =IF($A16="","",SUMIF(Bowling!$B:$B,$A16,Bowling!$D:$D)) -> 0 | S16: =IF($A16="","",SUMIF(Bowling!$B:$B,$A16,Bowling!$J:$J)) -> 9 | T16: =IF($A16="","",SUMIF(Bowling!$B:$B,$A16,Bowling!$K:$K)) -> 2 | U16: =IF($A16="","",SUMIF(Bowling!$B:$B,$A16,Bowling!$H:$H)) -> 2 | V16: =IF($A16="","",SUMIF(Bowling!$B:$B,$A16,Bowling!$I:$I)) -> 0 | W16: =IF($A16="","",SUMIF(Fielding!$B:$B,$A16,Fielding!$C:$C)) -> 1 | X16: =IF($A16="","",SUMIF(Fielding!$B:$B,$A16,Fielding!$D:$D)) -> 0 | Y16: =IF($A16="","",SUMIF(Fielding!$B:$B,$A16,Fielding!$E:$E)) -> 0
A17: =IFERROR(__xludf.DUMMYFUNCTION("""COMPUTED_VALUE"""),"P16") -> P16 | B17: {=IF(A17="","",XLOOKUP(A17,Players!A:A,Players!B:B,""))} -> Vivek | C17: =IF(A17="","", MAX( COUNTIF(Batting!B:B,A17), COUNTIF(Bowling!B:B,A17), COUNTIF(Fielding!B:B,A17) )) -> 5 | D17: =IF($A17="","",COUNTIF(Batting!$B:$B,$A17)) -> 5 | E17: =IF($A17="","",COUNTIFS(Batting!$B:$B,$A17,Batting!$G:$G,"No")) -> 0 | F17: =IF($A17="","",SUMIF(Batting!$B:$B,$A17,Batting!$C:$C)) -> 34 | G17: =IF($A17="","",SUMIF(Batting!$B:$B,$A17,Batting!$D:$D)) -> 73 | H17: =IF($A17="","",SUMIF(Batting!$B:$B,$A17,Batting!$E:$E)) -> 11 | I17: =IF($A17="","",SUMIF(Batting!$B:$B,$A17,Batting!$F:$F)) -> 9 | J17: =IF($A17="","",IF(($D17-$E17)=0,"-",ROUND($F17/($D17-$E17),2))) -> 6.8 | K17: =IF($A17="","",IF($G17=0,0,ROUND(($F17/$G17)*100,2))) -> 46.58 | L17: {=IF($A17="","", SUM( IF(Bowling!$B$2:$B1000=$A17, (INT(Bowling!$C$2:$C1000)*6) + ROUND((Bowling!$C$2:$C1000-INT(Bowling!$C$2:$C1000))*10,0), 0 ) ))} -> 0 | M17: =IF($A17="","",INT($L17/6) + MOD($L17,6)/10) -> 0 | N17: =IF($A17="","",SUMIF(Bowling!$B:$B,$A17,Bowling!$E:$E)) -> 0 | O17: =IF($A17="","",SUMIF(Bowling!$B:$B,$A17,Bowling!$F:$F)) -> 0 | P17: =IF($A17="","",IF($L17=0,0,ROUND($N17/($L17/6),2))) -> 0 | Q17: =IF($A17="","",SUMIF(Bowling!$B:$B,$A17,Bowling!$G:$G)) -> 0 | R17: =IF($A17="","",SUMIF(Bowling!$B:$B,$A17,Bowling!$D:$D)) -> 0 | S17: =IF($A17="","",SUMIF(Bowling!$B:$B,$A17,Bowling!$J:$J)) -> 0 | T17: =IF($A17="","",SUMIF(Bowling!$B:$B,$A17,Bowling!$K:$K)) -> 0 | U17: =IF($A17="","",SUMIF(Bowling!$B:$B,$A17,Bowling!$H:$H)) -> 0 | V17: =IF($A17="","",SUMIF(Bowling!$B:$B,$A17,Bowling!$I:$I)) -> 0 | W17: =IF($A17="","",SUMIF(Fielding!$B:$B,$A17,Fielding!$C:$C)) -> 1 | X17: =IF($A17="","",SUMIF(Fielding!$B:$B,$A17,Fielding!$D:$D)) -> 0 | Y17: =IF($A17="","",SUMIF(Fielding!$B:$B,$A17,Fielding!$E:$E)) -> 0
A18: =IFERROR(__xludf.DUMMYFUNCTION("""COMPUTED_VALUE"""),"P17") -> P17 | B18: {=IF(A18="","",XLOOKUP(A18,Players!A:A,Players!B:B,""))} -> Ahil | C18: =IF(A18="","", MAX( COUNTIF(Batting!B:B,A18), COUNTIF(Bowling!B:B,A18), COUNTIF(Fielding!B:B,A18) )) -> 2 | D18: =IF($A18="","",COUNTIF(Batting!$B:$B,$A18)) -> 2 | E18: =IF($A18="","",COUNTIFS(Batting!$B:$B,$A18,Batting!$G:$G,"No")) -> 0 | F18: =IF($A18="","",SUMIF(Batting!$B:$B,$A18,Batting!$C:$C)) -> 26 | G18: =IF($A18="","",SUMIF(Batting!$B:$B,$A18,Batting!$D:$D)) -> 22 | H18: =IF($A18="","",SUMIF(Batting!$B:$B,$A18,Batting!$E:$E)) -> 2 | I18: =IF($A18="","",SUMIF(Batting!$B:$B,$A18,Batting!$F:$F)) -> 2 | J18: =IF($A18="","",IF(($D18-$E18)=0,"-",ROUND($F18/($D18-$E18),2))) -> 13 | K18: =IF($A18="","",IF($G18=0,0,ROUND(($F18/$G18)*100,2))) -> 118.18 | L18: {=IF($A18="","", SUM( IF(Bowling!$B$2:$B1000=$A18, (INT(Bowling!$C$2:$C1000)*6) + ROUND((Bowling!$C$2:$C1000-INT(Bowling!$C$2:$C1000))*10,0), 0 ) ))} -> 0 | M18: =IF($A18="","",INT($L18/6) + MOD($L18,6)/10) -> 0 | N18: =IF($A18="","",SUMIF(Bowling!$B:$B,$A18,Bowling!$E:$E)) -> 0 | O18: =IF($A18="","",SUMIF(Bowling!$B:$B,$A18,Bowling!$F:$F)) -> 0 | P18: =IF($A18="","",IF($L18=0,0,ROUND($N18/($L18/6),2))) -> 0 | Q18: =IF($A18="","",SUMIF(Bowling!$B:$B,$A18,Bowling!$G:$G)) -> 0 | R18: =IF($A18="","",SUMIF(Bowling!$B:$B,$A18,Bowling!$D:$D)) -> 0 | S18: =IF($A18="","",SUMIF(Bowling!$B:$B,$A18,Bowling!$J:$J)) -> 0 | T18: =IF($A18="","",SUMIF(Bowling!$B:$B,$A18,Bowling!$K:$K)) -> 0 | U18: =IF($A18="","",SUMIF(Bowling!$B:$B,$A18,Bowling!$H:$H)) -> 0 | V18: =IF($A18="","",SUMIF(Bowling!$B:$B,$A18,Bowling!$I:$I)) -> 0 | W18: =IF($A18="","",SUMIF(Fielding!$B:$B,$A18,Fielding!$C:$C)) -> 0 | X18: =IF($A18="","",SUMIF(Fielding!$B:$B,$A18,Fielding!$D:$D)) -> 0 | Y18: =IF($A18="","",SUMIF(Fielding!$B:$B,$A18,Fielding!$E:$E)) -> 0
A19: =IFERROR(__xludf.DUMMYFUNCTION("""COMPUTED_VALUE"""),"P18") -> P18 | B19: {=IF(A19="","",XLOOKUP(A19,Players!A:A,Players!B:B,""))} -> Bhuvaneshvaran A | C19: =IF(A19="","", MAX( COUNTIF(Batting!B:B,A19), COUNTIF(Bowling!B:B,A19), COUNTIF(Fielding!B:B,A19) )) -> 4 | D19: =IF($A19="","",COUNTIF(Batting!$B:$B,$A19)) -> 4 | E19: =IF($A19="","",COUNTIFS(Batting!$B:$B,$A19,Batting!$G:$G,"No")) -> 0 | F19: =IF($A19="","",SUMIF(Batting!$B:$B,$A19,Batting!$C:$C)) -> 53 | G19: =IF($A19="","",SUMIF(Batting!$B:$B,$A19,Batting!$D:$D)) -> 70 | H19: =IF($A19="","",SUMIF(Batting!$B:$B,$A19,Batting!$E:$E)) -> 4 | I19: =IF($A19="","",SUMIF(Batting!$B:$B,$A19,Batting!$F:$F)) -> 1 | J19: =IF($A19="","",IF(($D19-$E19)=0,"-",ROUND($F19/($D19-$E19),2))) -> 13.25 | K19: =IF($A19="","",IF($G19=0,0,ROUND(($F19/$G19)*100,2))) -> 75.71 | L19: {=IF($A19="","", SUM( IF(Bowling!$B$2:$B1000=$A19, (INT(Bowling!$C$2:$C1000)*6) + ROUND((Bowling!$C$2:$C1000-INT(Bowling!$C$2:$C1000))*10,0), 0 ) ))} -> 100 | M19: =IF($A19="","",INT($L19/6) + MOD($L19,6)/10) -> 16.4 | N19: =IF($A19="","",SUMIF(Bowling!$B:$B,$A19,Bowling!$E:$E)) -> 111 | O19: =IF($A19="","",SUMIF(Bowling!$B:$B,$A19,Bowling!$F:$F)) -> 6 | P19: =IF($A19="","",IF($L19=0,0,ROUND($N19/($L19/6),2))) -> 6.66 | Q19: =IF($A19="","",SUMIF(Bowling!$B:$B,$A19,Bowling!$G:$G)) -> 32 | R19: =IF($A19="","",SUMIF(Bowling!$B:$B,$A19,Bowling!$D:$D)) -> 0 | S19: =IF($A19="","",SUMIF(Bowling!$B:$B,$A19,Bowling!$J:$J)) -> 13 | T19: =IF($A19="","",SUMIF(Bowling!$B:$B,$A19,Bowling!$K:$K)) -> 1 | U19: =IF($A19="","",SUMIF(Bowling!$B:$B,$A19,Bowling!$H:$H)) -> 4 | V19: =IF($A19="","",SUMIF(Bowling!$B:$B,$A19,Bowling!$I:$I)) -> 0 | W19: =IF($A19="","",SUMIF(Fielding!$B:$B,$A19,Fielding!$C:$C)) -> 4 | X19: =IF($A19="","",SUMIF(Fielding!$B:$B,$A19,Fielding!$D:$D)) -> 0 | Y19: =IF($A19="","",SUMIF(Fielding!$B:$B,$A19,Fielding!$E:$E)) -> 0
A20: =IFERROR(__xludf.DUMMYFUNCTION("""COMPUTED_VALUE"""),"P19") -> P19 | B20: {=IF(A20="","",XLOOKUP(A20,Players!A:A,Players!B:B,""))} -> Karthik | C20: =IF(A20="","", MAX( COUNTIF(Batting!B:B,A20), COUNTIF(Bowling!B:B,A20), COUNTIF(Fielding!B:B,A20) )) -> 1 | D20: =IF($A20="","",COUNTIF(Batting!$B:$B,$A20)) -> 1 | E20: =IF($A20="","",COUNTIFS(Batting!$B:$B,$A20,Batting!$G:$G,"No")) -> 1 | F20: =IF($A20="","",SUMIF(Batting!$B:$B,$A20,Batting!$C:$C)) -> 14 | G20: =IF($A20="","",SUMIF(Batting!$B:$B,$A20,Batting!$D:$D)) -> 23 | H20: =IF($A20="","",SUMIF(Batting!$B:$B,$A20,Batting!$E:$E)) -> 1 | I20: =IF($A20="","",SUMIF(Batting!$B:$B,$A20,Batting!$F:$F)) -> 0 | J20: =IF($A20="","",IF(($D20-$E20)=0,"-",ROUND($F20/($D20-$E20),2))) -> - | K20: =IF($A20="","",IF($G20=0,0,ROUND(($F20/$G20)*100,2))) -> 60.87 | L20: {=IF($A20="","", SUM( IF(Bowling!$B$2:$B1000=$A20, (INT(Bowling!$C$2:$C1000)*6) + ROUND((Bowling!$C$2:$C1000-INT(Bowling!$C$2:$C1000))*10,0), 0 ) ))} -> 18 | M20: =IF($A20="","",INT($L20/6) + MOD($L20,6)/10) -> 3 | N20: =IF($A20="","",SUMIF(Bowling!$B:$B,$A20,Bowling!$E:$E)) -> 14 | O20: =IF($A20="","",SUMIF(Bowling!$B:$B,$A20,Bowling!$F:$F)) -> 0 | P20: =IF($A20="","",IF($L20=0,0,ROUND($N20/($L20/6),2))) -> 4.67 | Q20: =IF($A20="","",SUMIF(Bowling!$B:$B,$A20,Bowling!$G:$G)) -> 14 | R20: =IF($A20="","",SUMIF(Bowling!$B:$B,$A20,Bowling!$D:$D)) -> 0 | S20: =IF($A20="","",SUMIF(Bowling!$B:$B,$A20,Bowling!$J:$J)) -> 2 | T20: =IF($A20="","",SUMIF(Bowling!$B:$B,$A20,Bowling!$K:$K)) -> 0 | U20: =IF($A20="","",SUMIF(Bowling!$B:$B,$A20,Bowling!$H:$H)) -> 2 | V20: =IF($A20="","",SUMIF(Bowling!$B:$B,$A20,Bowling!$I:$I)) -> 0 | W20: =IF($A20="","",SUMIF(Fielding!$B:$B,$A20,Fielding!$C:$C)) -> 0 | X20: =IF($A20="","",SUMIF(Fielding!$B:$B,$A20,Fielding!$D:$D)) -> 0 | Y20: =IF($A20="","",SUMIF(Fielding!$B:$B,$A20,Fielding!$E:$E)) -> 0
A21: =IFERROR(__xludf.DUMMYFUNCTION("""COMPUTED_VALUE"""),"P20") -> P20 | B21: {=IF(A21="","",XLOOKUP(A21,Players!A:A,Players!B:B,""))} -> Jagath | C21: =IF(A21="","", MAX( COUNTIF(Batting!B:B,A21), COUNTIF(Bowling!B:B,A21), COUNTIF(Fielding!B:B,A21) )) -> 1 | D21: =IF($A21="","",COUNTIF(Batting!$B:$B,$A21)) -> 0 | E21: =IF($A21="","",COUNTIFS(Batting!$B:$B,$A21,Batting!$G:$G,"No")) -> 0 | F21: =IF($A21="","",SUMIF(Batting!$B:$B,$A21,Batting!$C:$C)) -> 0 | G21: =IF($A21="","",SUMIF(Batting!$B:$B,$A21,Batting!$D:$D)) -> 0 | H21: =IF($A21="","",SUMIF(Batting!$B:$B,$A21,Batting!$E:$E)) -> 0 | I21: =IF($A21="","",SUMIF(Batting!$B:$B,$A21,Batting!$F:$F)) -> 0 | J21: =IF($A21="","",IF(($D21-$E21)=0,"-",ROUND($F21/($D21-$E21),2))) -> - | K21: =IF($A21="","",IF($G21=0,0,ROUND(($F21/$G21)*100,2))) -> 0 | L21: {=IF($A21="","", SUM( IF(Bowling!$B$2:$B1000=$A21, (INT(Bowling!$C$2:$C1000)*6) + ROUND((Bowling!$C$2:$C1000-INT(Bowling!$C$2:$C1000))*10,0), 0 ) ))} -> 18 | M21: =IF($A21="","",INT($L21/6) + MOD($L21,6)/10) -> 3 | N21: =IF($A21="","",SUMIF(Bowling!$B:$B,$A21,Bowling!$E:$E)) -> 15 | O21: =IF($A21="","",SUMIF(Bowling!$B:$B,$A21,Bowling!$F:$F)) -> 0 | P21: =IF($A21="","",IF($L21=0,0,ROUND($N21/($L21/6),2))) -> 5 | Q21: =IF($A21="","",SUMIF(Bowling!$B:$B,$A21,Bowling!$G:$G)) -> 10 | R21: =IF($A21="","",SUMIF(Bowling!$B:$B,$A21,Bowling!$D:$D)) -> 0 | S21: =IF($A21="","",SUMIF(Bowling!$B:$B,$A21,Bowling!$J:$J)) -> 1 | T21: =IF($A21="","",SUMIF(Bowling!$B:$B,$A21,Bowling!$K:$K)) -> 0 | U21: =IF($A21="","",SUMIF(Bowling!$B:$B,$A21,Bowling!$H:$H)) -> 2 | V21: =IF($A21="","",SUMIF(Bowling!$B:$B,$A21,Bowling!$I:$I)) -> 0 | W21: =IF($A21="","",SUMIF(Fielding!$B:$B,$A21,Fielding!$C:$C)) -> 0 | X21: =IF($A21="","",SUMIF(Fielding!$B:$B,$A21,Fielding!$D:$D)) -> 0 | Y21: =IF($A21="","",SUMIF(Fielding!$B:$B,$A21,Fielding!$E:$E)) -> 0
A22: =IFERROR(__xludf.DUMMYFUNCTION("""COMPUTED_VALUE"""),"P21") -> P21 | B22: {=IF(A22="","",XLOOKUP(A22,Players!A:A,Players!B:B,""))} -> Saibullah | C22: =IF(A22="","", MAX( COUNTIF(Batting!B:B,A22), COUNTIF(Bowling!B:B,A22), COUNTIF(Fielding!B:B,A22) )) -> 3 | D22: =IF($A22="","",COUNTIF(Batting!$B:$B,$A22)) -> 3 | E22: =IF($A22="","",COUNTIFS(Batting!$B:$B,$A22,Batting!$G:$G,"No")) -> 0 | F22: =IF($A22="","",SUMIF(Batting!$B:$B,$A22,Batting!$C:$C)) -> 0 | G22: =IF($A22="","",SUMIF(Batting!$B:$B,$A22,Batting!$D:$D)) -> 11 | H22: =IF($A22="","",SUMIF(Batting!$B:$B,$A22,Batting!$E:$E)) -> 0 | I22: =IF($A22="","",SUMIF(Batting!$B:$B,$A22,Batting!$F:$F)) -> 0 | J22: =IF($A22="","",IF(($D22-$E22)=0,"-",ROUND($F22/($D22-$E22),2))) -> 0 | K22: =IF($A22="","",IF($G22=0,0,ROUND(($F22/$G22)*100,2))) -> 0 | L22: {=IF($A22="","", SUM( IF(Bowling!$B$2:$B1000=$A22, (INT(Bowling!$C$2:$C1000)*6) + ROUND((Bowling!$C$2:$C1000-INT(Bowling!$C$2:$C1000))*10,0), 0 ) ))} -> 0 | M22: =IF($A22="","",INT($L22/6) + MOD($L22,6)/10) -> 0 | N22: =IF($A22="","",SUMIF(Bowling!$B:$B,$A22,Bowling!$E:$E)) -> 0 | O22: =IF($A22="","",SUMIF(Bowling!$B:$B,$A22,Bowling!$F:$F)) -> 0 | P22: =IF($A22="","",IF($L22=0,0,ROUND($N22/($L22/6),2))) -> 0 | Q22: =IF($A22="","",SUMIF(Bowling!$B:$B,$A22,Bowling!$G:$G)) -> 0 | R22: =IF($A22="","",SUMIF(Bowling!$B:$B,$A22,Bowling!$D:$D)) -> 0 | S22: =IF($A22="","",SUMIF(Bowling!$B:$B,$A22,Bowling!$J:$J)) -> 0 | T22: =IF($A22="","",SUMIF(Bowling!$B:$B,$A22,Bowling!$K:$K)) -> 0 | U22: =IF($A22="","",SUMIF(Bowling!$B:$B,$A22,Bowling!$H:$H)) -> 0 | V22: =IF($A22="","",SUMIF(Bowling!$B:$B,$A22,Bowling!$I:$I)) -> 0 | W22: =IF($A22="","",SUMIF(Fielding!$B:$B,$A22,Fielding!$C:$C)) -> 0 | X22: =IF($A22="","",SUMIF(Fielding!$B:$B,$A22,Fielding!$D:$D)) -> 0 | Y22: =IF($A22="","",SUMIF(Fielding!$B:$B,$A22,Fielding!$E:$E)) -> 0
A23: =IFERROR(__xludf.DUMMYFUNCTION("""COMPUTED_VALUE"""),"P22") -> P22 | B23: {=IF(A23="","",XLOOKUP(A23,Players!A:A,Players!B:B,""))} -> Prasanth G | C23: =IF(A23="","", MAX( COUNTIF(Batting!B:B,A23), COUNTIF(Bowling!B:B,A23), COUNTIF(Fielding!B:B,A23) )) -> 1 | D23: =IF($A23="","",COUNTIF(Batting!$B:$B,$A23)) -> 1 | E23: =IF($A23="","",COUNTIFS(Batting!$B:$B,$A23,Batting!$G:$G,"No")) -> 0 | F23: =IF($A23="","",SUMIF(Batting!$B:$B,$A23,Batting!$C:$C)) -> 2 | G23: =IF($A23="","",SUMIF(Batting!$B:$B,$A23,Batting!$D:$D)) -> 12 | H23: =IF($A23="","",SUMIF(Batting!$B:$B,$A23,Batting!$E:$E)) -> 0 | I23: =IF($A23="","",SUMIF(Batting!$B:$B,$A23,Batting!$F:$F)) -> 0 | J23: =IF($A23="","",IF(($D23-$E23)=0,"-",ROUND($F23/($D23-$E23),2))) -> 2 | K23: =IF($A23="","",IF($G23=0,0,ROUND(($F23/$G23)*100,2))) -> 16.67 | L23: {=IF($A23="","", SUM( IF(Bowling!$B$2:$B1000=$A23, (INT(Bowling!$C$2:$C1000)*6) + ROUND((Bowling!$C$2:$C1000-INT(Bowling!$C$2:$C1000))*10,0), 0 ) ))} -> 12 | M23: =IF($A23="","",INT($L23/6) + MOD($L23,6)/10) -> 2 | N23: =IF($A23="","",SUMIF(Bowling!$B:$B,$A23,Bowling!$E:$E)) -> 13 | O23: =IF($A23="","",SUMIF(Bowling!$B:$B,$A23,Bowling!$F:$F)) -> 0 | P23: =IF($A23="","",IF($L23=0,0,ROUND($N23/($L23/6),2))) -> 6.5 | Q23: =IF($A23="","",SUMIF(Bowling!$B:$B,$A23,Bowling!$G:$G)) -> 9 | R23: =IF($A23="","",SUMIF(Bowling!$B:$B,$A23,Bowling!$D:$D)) -> 0 | S23: =IF($A23="","",SUMIF(Bowling!$B:$B,$A23,Bowling!$J:$J)) -> 3 | T23: =IF($A23="","",SUMIF(Bowling!$B:$B,$A23,Bowling!$K:$K)) -> 0 | U23: =IF($A23="","",SUMIF(Bowling!$B:$B,$A23,Bowling!$H:$H)) -> 0 | V23: =IF($A23="","",SUMIF(Bowling!$B:$B,$A23,Bowling!$I:$I)) -> 1 | Y23: =IF($A23="","",SUMIF(Fielding!$B:$B,$A23,Fielding!$E:$E)) -> 0
A24: =IFERROR(__xludf.DUMMYFUNCTION("""COMPUTED_VALUE"""),"P23") -> P23 | B24: {=IF(A24="","",XLOOKUP(A24,Players!A:A,Players!B:B,""))} -> Manoj | C24: =IF(A24="","", MAX( COUNTIF(Batting!B:B,A24), COUNTIF(Bowling!B:B,A24), COUNTIF(Fielding!B:B,A24) )) -> 2 | D24: =IF($A24="","",COUNTIF(Batting!$B:$B,$A24)) -> 2 | E24: =IF($A24="","",COUNTIFS(Batting!$B:$B,$A24,Batting!$G:$G,"No")) -> 0 | F24: =IF($A24="","",SUMIF(Batting!$B:$B,$A24,Batting!$C:$C)) -> 16 | G24: =IF($A24="","",SUMIF(Batting!$B:$B,$A24,Batting!$D:$D)) -> 14 | H24: =IF($A24="","",SUMIF(Batting!$B:$B,$A24,Batting!$E:$E)) -> 4 | I24: =IF($A24="","",SUMIF(Batting!$B:$B,$A24,Batting!$F:$F)) -> 0 | J24: =IF($A24="","",IF(($D24-$E24)=0,"-",ROUND($F24/($D24-$E24),2))) -> 8 | K24: =IF($A24="","",IF($G24=0,0,ROUND(($F24/$G24)*100,2))) -> 114.29 | L24: {=IF($A24="","", SUM( IF(Bowling!$B$2:$B1000=$A24, (INT(Bowling!$C$2:$C1000)*6) + ROUND((Bowling!$C$2:$C1000-INT(Bowling!$C$2:$C1000))*10,0), 0 ) ))} -> 54 | M24: =IF($A24="","",INT($L24/6) + MOD($L24,6)/10) -> 9 | N24: =IF($A24="","",SUMIF(Bowling!$B:$B,$A24,Bowling!$E:$E)) -> 42 | O24: =IF($A24="","",SUMIF(Bowling!$B:$B,$A24,Bowling!$F:$F)) -> 3 | P24: =IF($A24="","",IF($L24=0,0,ROUND($N24/($L24/6),2))) -> 4.67 | Q24: =IF($A24="","",SUMIF(Bowling!$B:$B,$A24,Bowling!$G:$G)) -> 33 | R24: =IF($A24="","",SUMIF(Bowling!$B:$B,$A24,Bowling!$D:$D)) -> 0 | S24: =IF($A24="","",SUMIF(Bowling!$B:$B,$A24,Bowling!$J:$J)) -> 1 | T24: =IF($A24="","",SUMIF(Bowling!$B:$B,$A24,Bowling!$K:$K)) -> 1 | U24: =IF($A24="","",SUMIF(Bowling!$B:$B,$A24,Bowling!$H:$H)) -> 5 | V24: =IF($A24="","",SUMIF(Bowling!$B:$B,$A24,Bowling!$I:$I)) -> 0 | Y24: =IF($A24="","",SUMIF(Fielding!$B:$B,$A24,Fielding!$E:$E)) -> 0
A25: =IFERROR(__xludf.DUMMYFUNCTION("""COMPUTED_VALUE"""),"P24") -> P24 | B25: {=IF(A25="","",XLOOKUP(A25,Players!A:A,Players!B:B,""))} -> Imtiyaz | C25: =IF(A25="","", MAX( COUNTIF(Batting!B:B,A25), COUNTIF(Bowling!B:B,A25), COUNTIF(Fielding!B:B,A25) )) -> 1 | D25: =IF($A25="","",COUNTIF(Batting!$B:$B,$A25)) -> 1 | E25: =IF($A25="","",COUNTIFS(Batting!$B:$B,$A25,Batting!$G:$G,"No")) -> 0 | F25: =IF($A25="","",SUMIF(Batting!$B:$B,$A25,Batting!$C:$C)) -> 1 | G25: =IF($A25="","",SUMIF(Batting!$B:$B,$A25,Batting!$D:$D)) -> 7 | H25: =IF($A25="","",SUMIF(Batting!$B:$B,$A25,Batting!$E:$E)) -> 0 | I25: =IF($A25="","",SUMIF(Batting!$B:$B,$A25,Batting!$F:$F)) -> 0 | J25: =IF($A25="","",IF(($D25-$E25)=0,"-",ROUND($F25/($D25-$E25),2))) -> 1 | K25: =IF($A25="","",IF($G25=0,0,ROUND(($F25/$G25)*100,2))) -> 14.29 | L25: {=IF($A25="","", SUM( IF(Bowling!$B$2:$B1000=$A25, (INT(Bowling!$C$2:$C1000)*6) + ROUND((Bowling!$C$2:$C1000-INT(Bowling!$C$2:$C1000))*10,0), 0 ) ))} -> 0 | M25: =IF($A25="","",INT($L25/6) + MOD($L25,6)/10) -> 0 | N25: =IF($A25="","",SUMIF(Bowling!$B:$B,$A25,Bowling!$E:$E)) -> 0 | O25: =IF($A25="","",SUMIF(Bowling!$B:$B,$A25,Bowling!$F:$F)) -> 0 | P25: =IF($A25="","",IF($L25=0,0,ROUND($N25/($L25/6),2))) -> 0 | Q25: =IF($A25="","",SUMIF(Bowling!$B:$B,$A25,Bowling!$G:$G)) -> 0 | R25: =IF($A25="","",SUMIF(Bowling!$B:$B,$A25,Bowling!$D:$D)) -> 0 | S25: =IF($A25="","",SUMIF(Bowling!$B:$B,$A25,Bowling!$J:$J)) -> 0 | T25: =IF($A25="","",SUMIF(Bowling!$B:$B,$A25,Bowling!$K:$K)) -> 0 | U25: =IF($A25="","",SUMIF(Bowling!$B:$B,$A25,Bowling!$H:$H)) -> 0 | V25: =IF($A25="","",SUMIF(Bowling!$B:$B,$A25,Bowling!$I:$I)) -> 0
A26: =IFERROR(__xludf.DUMMYFUNCTION("""COMPUTED_VALUE"""),"P25") -> P25 | B26: {=IF(A26="","",XLOOKUP(A26,Players!A:A,Players!B:B,""))} -> Vivek VNA | C26: =IF(A26="","", MAX( COUNTIF(Batting!B:B,A26), COUNTIF(Bowling!B:B,A26), COUNTIF(Fielding!B:B,A26) )) -> 1 | D26: =IF($A26="","",COUNTIF(Batting!$B:$B,$A26)) -> 0 | E26: =IF($A26="","",COUNTIFS(Batting!$B:$B,$A26,Batting!$G:$G,"No")) -> 0 | F26: =IF($A26="","",SUMIF(Batting!$B:$B,$A26,Batting!$C:$C)) -> 0 | G26: =IF($A26="","",SUMIF(Batting!$B:$B,$A26,Batting!$D:$D)) -> 0 | H26: =IF($A26="","",SUMIF(Batting!$B:$B,$A26,Batting!$E:$E)) -> 0 | I26: =IF($A26="","",SUMIF(Batting!$B:$B,$A26,Batting!$F:$F)) -> 0 | J26: =IF($A26="","",IF(($D26-$E26)=0,"-",ROUND($F26/($D26-$E26),2))) -> - | K26: =IF($A26="","",IF($G26=0,0,ROUND(($F26/$G26)*100,2))) -> 0 | L26: {=IF($A26="","", SUM( IF(Bowling!$B$2:$B1000=$A26, (INT(Bowling!$C$2:$C1000)*6) + ROUND((Bowling!$C$2:$C1000-INT(Bowling!$C$2:$C1000))*10,0), 0 ) ))} -> 12 | M26: =IF($A26="","",INT($L26/6) + MOD($L26,6)/10) -> 2 | N26: =IF($A26="","",SUMIF(Bowling!$B:$B,$A26,Bowling!$E:$E)) -> 27 | O26: =IF($A26="","",SUMIF(Bowling!$B:$B,$A26,Bowling!$F:$F)) -> 0 | P26: =IF($A26="","",IF($L26=0,0,ROUND($N26/($L26/6),2))) -> 13.5 | Q26: =IF($A26="","",SUMIF(Bowling!$B:$B,$A26,Bowling!$G:$G)) -> 5 | R26: =IF($A26="","",SUMIF(Bowling!$B:$B,$A26,Bowling!$D:$D)) -> 0 | S26: =IF($A26="","",SUMIF(Bowling!$B:$B,$A26,Bowling!$J:$J)) -> 2 | T26: =IF($A26="","",SUMIF(Bowling!$B:$B,$A26,Bowling!$K:$K)) -> 0 | U26: =IF($A26="","",SUMIF(Bowling!$B:$B,$A26,Bowling!$H:$H)) -> 6 | V26: =IF($A26="","",SUMIF(Bowling!$B:$B,$A26,Bowling!$I:$I)) -> 0
B27: {=IF(A27="","",XLOOKUP(A27,Players!A:A,Players!B:B,""))} | C27: =IF(A27="","", MAX( COUNTIF(Batting!B:B,A27), COUNTIF(Bowling!B:B,A27), COUNTIF(Fielding!B:B,A27) )) | D27: =IF($A27="","",COUNTIF(Batting!$B:$B,$A27)) | E27: =IF($A27="","",COUNTIFS(Batting!$B:$B,$A27,Batting!$G:$G,"No")) | F27: =IF($A27="","",SUMIF(Batting!$B:$B,$A27,Batting!$C:$C)) | G27: =IF($A27="","",SUMIF(Batting!$B:$B,$A27,Batting!$D:$D)) | H27: =IF($A27="","",SUMIF(Batting!$B:$B,$A27,Batting!$E:$E)) | I27: =IF($A27="","",SUMIF(Batting!$B:$B,$A27,Batting!$F:$F)) | J27: =IF($A27="","",IF(($D27-$E27)=0,"-",ROUND($F27/($D27-$E27),2))) | K27: =IF($A27="","",IF($G27=0,0,ROUND(($F27/$G27)*100,2))) | L27: {=IF($A27="","", SUM( IF(Bowling!$B$2:$B1000=$A27, (INT(Bowling!$C$2:$C1000)*6) + ROUND((Bowling!$C$2:$C1000-INT(Bowling!$C$2:$C1000))*10,0), 0 ) ))} | M27: =IF($A27="","",INT($L27/6) + MOD($L27,6)/10) | N27: =IF($A27="","",SUMIF(Bowling!$B:$B,$A27,Bowling!$E:$E)) | O27: =IF($A27="","",SUMIF(Bowling!$B:$B,$A27,Bowling!$F:$F)) | P27: =IF($A27="","",IF($L27=0,0,ROUND($N27/($L27/6),2))) | Q27: =IF($A27="","",SUMIF(Bowling!$B:$B,$A27,Bowling!$G:$G)) | R27: =IF($A27="","",SUMIF(Bowling!$B:$B,$A27,Bowling!$D:$D)) | S27: =IF($A27="","",SUMIF(Bowling!$B:$B,$A27,Bowling!$J:$J)) | T27: =IF($A27="","",SUMIF(Bowling!$B:$B,$A27,Bowling!$K:$K)) | U27: =IF($A27="","",SUMIF(Bowling!$B:$B,$A27,Bowling!$H:$H)) | V27: =IF($A27="","",SUMIF(Bowling!$B:$B,$A27,Bowling!$I:$I))
B28: {=IF(A28="","",XLOOKUP(A28,Players!A:A,Players!B:B,""))} | C28: =IF(A28="","", MAX( COUNTIF(Batting!B:B,A28), COUNTIF(Bowling!B:B,A28), COUNTIF(Fielding!B:B,A28) )) | D28: =IF($A28="","",COUNTIF(Batting!$B:$B,$A28)) | E28: =IF($A28="","",COUNTIFS(Batting!$B:$B,$A28,Batting!$G:$G,"No")) | F28: =IF($A28="","",SUMIF(Batting!$B:$B,$A28,Batting!$C:$C)) | G28: =IF($A28="","",SUMIF(Batting!$B:$B,$A28,Batting!$D:$D)) | H28: =IF($A28="","",SUMIF(Batting!$B:$B,$A28,Batting!$E:$E)) | I28: =IF($A28="","",SUMIF(Batting!$B:$B,$A28,Batting!$F:$F)) | J28: =IF($A28="","",IF(($D28-$E28)=0,"-",ROUND($F28/($D28-$E28),2))) | K28: =IF($A28="","",IF($G28=0,0,ROUND(($F28/$G28)*100,2))) | L28: {=IF($A28="","", SUM( IF(Bowling!$B$2:$B1000=$A28, (INT(Bowling!$C$2:$C1000)*6) + ROUND((Bowling!$C$2:$C1000-INT(Bowling!$C$2:$C1000))*10,0), 0 ) ))} | M28: =IF($A28="","",INT($L28/6) + MOD($L28,6)/10) | N28: =IF($A28="","",SUMIF(Bowling!$B:$B,$A28,Bowling!$E:$E)) | O28: =IF($A28="","",SUMIF(Bowling!$B:$B,$A28,Bowling!$F:$F)) | P28: =IF($A28="","",IF($L28=0,0,ROUND($N28/($L28/6),2))) | Q28: =IF($A28="","",SUMIF(Bowling!$B:$B,$A28,Bowling!$G:$G)) | R28: =IF($A28="","",SUMIF(Bowling!$B:$B,$A28,Bowling!$D:$D)) | S28: =IF($A28="","",SUMIF(Bowling!$B:$B,$A28,Bowling!$J:$J)) | T28: =IF($A28="","",SUMIF(Bowling!$B:$B,$A28,Bowling!$K:$K)) | U28: =IF($A28="","",SUMIF(Bowling!$B:$B,$A28,Bowling!$H:$H)) | V28: =IF($A28="","",SUMIF(Bowling!$B:$B,$A28,Bowling!$I:$I))
B29: {=IF(A29="","",XLOOKUP(A29,Players!A:A,Players!B:B,""))} | C29: =IF(A29="","", MAX( COUNTIF(Batting!B:B,A29), COUNTIF(Bowling!B:B,A29), COUNTIF(Fielding!B:B,A29) )) | D29: =IF($A29="","",COUNTIF(Batting!$B:$B,$A29)) | E29: =IF($A29="","",COUNTIFS(Batting!$B:$B,$A29,Batting!$G:$G,"No")) | F29: =IF($A29="","",SUMIF(Batting!$B:$B,$A29,Batting!$C:$C)) | G29: =IF($A29="","",SUMIF(Batting!$B:$B,$A29,Batting!$D:$D)) | H29: =IF($A29="","",SUMIF(Batting!$B:$B,$A29,Batting!$E:$E)) | I29: =IF($A29="","",SUMIF(Batting!$B:$B,$A29,Batting!$F:$F)) | J29: =IF($A29="","",IF(($D29-$E29)=0,"-",ROUND($F29/($D29-$E29),2))) | K29: =IF($A29="","",IF($G29=0,0,ROUND(($F29/$G29)*100,2))) | L29: {=IF($A29="","", SUM( IF(Bowling!$B$2:$B1000=$A29, (INT(Bowling!$C$2:$C1000)*6) + ROUND((Bowling!$C$2:$C1000-INT(Bowling!$C$2:$C1000))*10,0), 0 ) ))} | M29: =IF($A29="","",INT($L29/6) + MOD($L29,6)/10) | N29: =IF($A29="","",SUMIF(Bowling!$B:$B,$A29,Bowling!$E:$E)) | O29: =IF($A29="","",SUMIF(Bowling!$B:$B,$A29,Bowling!$F:$F)) | P29: =IF($A29="","",IF($L29=0,0,ROUND($N29/($L29/6),2))) | Q29: =IF($A29="","",SUMIF(Bowling!$B:$B,$A29,Bowling!$G:$G)) | R29: =IF($A29="","",SUMIF(Bowling!$B:$B,$A29,Bowling!$D:$D)) | S29: =IF($A29="","",SUMIF(Bowling!$B:$B,$A29,Bowling!$J:$J)) | T29: =IF($A29="","",SUMIF(Bowling!$B:$B,$A29,Bowling!$K:$K)) | U29: =IF($A29="","",SUMIF(Bowling!$B:$B,$A29,Bowling!$H:$H)) | V29: =IF($A29="","",SUMIF(Bowling!$B:$B,$A29,Bowling!$I:$I))
